Workbook

Sheet Rekap_Manager
A2: Surabraja — monitoring checklist harian
A4: Tanggal pantau | B4: 46299 | D4: Tanggal dapat diganti. Rekap menghitung kegiatan dan kelengkapan laporan harian.
A5: Persentase selesai = kegiatan Selesai / kegiatan berlaku. Tidak Berlaku dikecualikan.
A7: Jabatan | B7: PIC aktif | C7: Dikirim | D7: Belum lapor | E7: Draft | F7: Menunggu review | G7: Perlu perbaikan
A8: Sales | B8: =COUNTIFS($C$20:$C$79,$A8) -> 26 | C8: =COUNTIFS($C$20:$C$79,$A8,$G$20:$G$79,"Dikirim") -> 0 | D8: =COUNTIFS($C$20:$C$79,$A8,$G$20:$G$79,"Belum Lapor") -> 26 | E8: =COUNTIFS($C$20:$C$79,$A8,$G$20:$G$79,"Draft") -> 0 | F8: =COUNTIFS($C$20:$C$79,$A8,$N$20:$N$79,"Belum Diperiksa") -> 0 | G8: =COUNTIFS($C$20:$C$79,$A8,$N$20:$N$79,"Perlu Perbaikan") -> 0
A9: SPV | B9: =COUNTIFS($C$20:$C$79,$A9) -> 1 | C9: =COUNTIFS($C$20:$C$79,$A9,$G$20:$G$79,"Dikirim") -> 0 | D9: =COUNTIFS($C$20:$C$79,$A9,$G$20:$G$79,"Belum Lapor") -> 1 | E9: =COUNTIFS($C$20:$C$79,$A9,$G$20:$G$79,"Draft") -> 0 | F9: =COUNTIFS($C$20:$C$79,$A9,$N$20:$N$79,"Belum Diperiksa") -> 0 | G9: =COUNTIFS($C$20:$C$79,$A9,$N$20:$N$79,"Perlu Perbaikan") -> 0
A10: ASM | B10: =COUNTIFS($C$20:$C$79,$A10) -> 1 | C10: =COUNTIFS($C$20:$C$79,$A10,$G$20:$G$79,"Dikirim") -> 0 | D10: =COUNTIFS($C$20:$C$79,$A10,$G$20:$G$79,"Belum Lapor") -> 1 | E10: =COUNTIFS($C$20:$C$79,$A10,$G$20:$G$79,"Draft") -> 0 | F10: =COUNTIFS($C$20:$C$79,$A10,$N$20:$N$79,"Belum Diperiksa") -> 0 | G10: =COUNTIFS($C$20:$C$79,$A10,$N$20:$N$79,"Perlu Perbaikan") -> 0
A12: Pemeriksaan | B12: =IF(COUNTA(Master_PIC!$A$8:$A$73)=0,"Isi Master_PIC terlebih dahulu",IF(COUNTIFS($G$20:$G$79,"Data Ganda")>0,"Ada laporan ganda",IF(COUNTIFS($G$20:$G$79,"Belum Lapor")>0,"Ada PIC belum melapor","Lihat detail laporan"))) -> Ada PIC belum melapor
A14: Alur review: Sales oleh SPV, SPV oleh ASM, ASM oleh Manager Sales & Marketing.
A15: Status Selesai berarti seluruh bagian kegiatan yang berlaku telah dikerjakan. Catat outlet/agenda yang terlewat.
A17: Detail per PIC
A19: ID PIC | B19: Nama PIC | C19: Jabatan | D19: Cabang | E19: Area | F19: Baris laporan | G19: Laporan harian | H19: Kegiatan berlaku | I19: Selesai | J19: Proses | K19: Belum | L19: Kosong | M19: % selesai | N19: Hasil review | O19: Perhatian
A20: =IF(AND(Master_PIC!A12<>"",Master_PIC!G12="Aktif",Master_PIC!C12<>"Manager"),Master_PIC!A12,"") -> Sales01 | B20: =IF($A20="","",IF(Master_PIC!B12="","",Master_PIC!B12)) -> Mahfud/Apud SBFI | C20: =IF($A20="","",IF(Master_PIC!C12="","",Master_PIC!C12)) -> Sales | D20: =IF($A20="","",IF(Master_PIC!D12="","",Master_PIC!D12)) -> Cirebon 1 (Lokal) | E20: =IF($A20="","",IF(Master_PIC!E12="","",Master_PIC!E12)) -> Timur | F20: =IF($A20="","",COUNTIFS(Sales_Harian!$A$8:$A$507,$B$4,Sales_Harian!$B$8:$B$507,$A20)+COUNTIFS(SPV_Harian!$A$8:$A$507,$B$4,SPV_Harian!$B$8:$B$507,$A20)+COUNTIFS(ASM_Harian!$A$8:$A$507,$B$4,ASM_Harian!$B$8:$B$507,$A20)) -> 0 | G20: =IF($A20="","",IF(F20=0,"Belum Lapor",IF(F20>1,"Data Ganda",IF(COUNTIFS(Sales_Harian!$A$8:$A$507,$B$4,Sales_Harian!$B$8:$B$507,$A20,Sales_Harian!$Z$8:$Z$507,"Dikirim")+COUNTIFS(SPV_Harian!$A$8:$A$507,$B$4,SPV_Harian!$B$8:$B$507,$A20,SPV_Harian!$Y$8:$Y$507,"Dikirim")+COUNTIFS(ASM_Harian!$A$8:$A$507,$B$4,ASM_Harian!$B$8:$B$507,$A20,ASM_Harian!$Y$8:$Y$507,"Dikirim")=1,"Dikirim","Draft")))) -> Belum Lapor | H20: =IF(OR($A20="",F20=0),"",SUMIFS(Sales_Harian!$AF$8:$AF$507,Sales_Harian!$A$8:$A$507,$B$4,Sales_Harian!$B$8:$B$507,$A20)+SUMIFS(SPV_Harian!$AE$8:$AE$507,SPV_Harian!$A$8:$A$507,$B$4,SPV_Harian!$B$8:$B$507,$A20)+SUMIFS(ASM_Harian!$AE$8:$AE$507,ASM_Harian!$A$8:$A$507,$B$4,ASM_Harian!$B$8:$B$507,$A20)) | I20: =IF(OR($A20="",F20=0),"",SUMIFS(Sales_Harian!$AG$8:$AG$507,Sales_Harian!$A$8:$A$507,$B$4,Sales_Harian!$B$8:$B$507,$A20)+SUMIFS(SPV_Harian!$AF$8:$AF$507,SPV_Harian!$A$8:$A$507,$B$4,SPV_Harian!$B$8:$B$507,$A20)+SUMIFS(ASM_Harian!$AF$8:$AF$507,ASM_Harian!$A$8:$A$507,$B$4,ASM_Harian!$B$8:$B$507,$A20)) | J20: =IF(OR($A20="",F20=0),"",SUMIFS(Sales_Harian!$AH$8:$AH$507,Sales_Harian!$A$8:$A$507,$B$4,Sales_Harian!$B$8:$B$507,$A20)+SUMIFS(SPV_Harian!$AG$8:$AG$507,SPV_Harian!$A$8:$A$507,$B$4,SPV_Harian!$B$8:$B$507,$A20)+SUMIFS(ASM_Harian!$AG$8:$AG$507,ASM_Harian!$A$8:$A$507,$B$4,ASM_Harian!$B$8:$B$507,$A20)) | K20: =IF(OR($A20="",F20=0),"",SUMIFS(Sales_Harian!$AI$8:$AI$507,Sales_Harian!$A$8:$A$507,$B$4,Sales_Harian!$B$8:$B$507,$A20)+SUMIFS(SPV_Harian!$AH$8:$AH$507,SPV_Harian!$A$8:$A$507,$B$4,SPV_Harian!$B$8:$B$507,$A20)+SUMIFS(ASM_Harian!$AH$8:$AH$507,ASM_Harian!$A$8:$A$507,$B$4,ASM_Harian!$B$8:$B$507,$A20)) | L20: =IF(OR($A20="",F20=0),"",SUMIFS(Sales_Harian!$AK$8:$AK$507,Sales_Harian!$A$8:$A$507,$B$4,Sales_Harian!$B$8:$B$507,$A20)+SUMIFS(SPV_Harian!$AJ$8:$AJ$507,SPV_Harian!$A$8:$A$507,$B$4,SPV_Harian!$B$8:$B$507,$A20)+SUMIFS(ASM_Harian!$AJ$8:$AJ$507,ASM_Harian!$A$8:$A$507,$B$4,ASM_Harian!$B$8:$B$507,$A20)) | M20: =IF($A20="","",IF(OR(F20<>1,H20=0),"n.a.",I20/H20)) -> n.a. | N20: =IF($A20="","",IF(G20<>"Dikirim","",IF(COUNTIFS(Sales_Harian!$A$8:$A$507,$B$4,Sales_Harian!$B$8:$B$507,$A20,Sales_Harian!$AB$8:$AB$507,"Disetujui")+COUNTIFS(SPV_Harian!$A$8:$A$507,$B$4,SPV_Harian!$B$8:$B$507,$A20,SPV_Harian!$AA$8:$AA$507,"Disetujui")+COUNTIFS(ASM_Harian!$A$8:$A$507,$B$4,ASM_Harian!$B$8:$B$507,$A20,ASM_Harian!$AA$8:$AA$507,"Disetujui")=1,IF(COUNTIFS(Sales_Harian!$A$8:$A$507,$B$4,Sales_Harian!$B$8:$B$507,$A20,Sales_Harian!$AM$8:$AM$507,"<>OK")+COUNTIFS(SPV_Harian!$A$8:$A$507,$B$4,SPV_Harian!$B$8:$B$507,$A20,SPV_Harian!$AL$8:$AL$507,"<>OK")+COUNTIFS(ASM_Harian!$A$8:$A$507,$B$4,ASM_Harian!$B$8:$B$507,$A20,ASM_Harian!$AL$8:$AL$507,"<>OK")>0,"Review belum valid","Disetujui"),IF(COUNTIFS(Sales_Harian!$A$8:$A$507,$B$4,Sales_Harian!$B$8:$B$507,$A20,Sales_Harian!$AB$8:$AB$507,"Perlu Perbaikan")+COUNTIFS(SPV_Harian!$A$8:$A$507,$B$4,SPV_Harian!$B$8:$B$507,$A20,SPV_Harian!$AA$8:$AA$507,"Perlu Perbaikan")+COUNTIFS(ASM_Harian!$A$8:$A$507,$B$4,ASM_Harian!$B$8:$B$507,$A20,ASM_Harian!$AA$8:$AA$507,"Perlu Perbaikan")=1,"Perlu Perbaikan","Belum Diperiksa")))) | O20: =IF($A20="","",IF(F20=0,"Belum ada laporan",IF(F20>1,"Hapus/benahi laporan ganda",IF(COUNTIFS(Sales_Harian!$A$8:$A$507,$B$4,Sales_Harian!$B$8:$B$507,$A20,Sales_Harian!$AM$8:$AM$507,"<>OK")+COUNTIFS(SPV_Harian!$A$8:$A$507,$B$4,SPV_Harian!$B$8:$B$507,$A20,SPV_Harian!$AL$8:$AL$507,"<>OK")+COUNTIFS(ASM_Harian!$A$8:$A$507,$B$4,ASM_Harian!$B$8:$B$507,$A20,ASM_Harian!$AL$8:$AL$507,"<>OK")>0,"Periksa validasi_data",IF(SUM(J20:K20)>0,"Ada kegiatan terbuka",IF(N20="Perlu Perbaikan","Tindak lanjuti review",IF(G20="Draft","Kirim laporan",IF(N20="Belum Diperiksa","Menunggu pemeriksaan","")))))))) -> Belum ada laporan
A21: =IF(AND(Master_PIC!A10<>"",Master_PIC!G10="Aktif",Master_PIC!C10<>"Manager"),Master_PIC!A10,"") -> SPV01 | B21: =IF($A21="","",IF(Master_PIC!B10="","",Master_PIC!B10)) -> Moch Nurrizki Arief Wihadi | C21: =IF($A21="","",IF(Master_PIC!C10="","",Master_PIC!C10)) -> SPV | D21: =IF($A21="","",IF(Master_PIC!D10="","",Master_PIC!D10)) -> Cirebon 1 (Lokal) | E21: =IF($A21="","",IF(Master_PIC!E10="","",Master_PIC!E10)) -> Timur | F21: =IF($A21="","",COUNTIFS(Sales_Harian!$A$8:$A$507,$B$4,Sales_Harian!$B$8:$B$507,$A21)+COUNTIFS(SPV_Harian!$A$8:$A$507,$B$4,SPV_Harian!$B$8:$B$507,$A21)+COUNTIFS(ASM_Harian!$A$8:$A$507,$B$4,ASM_Harian!$B$8:$B$507,$A21)) -> 0 | G21: =IF($A21="","",IF(F21=0,"Belum Lapor",IF(F21>1,"Data Ganda",IF(COUNTIFS(Sales_Harian!$A$8:$A$507,$B$4,Sales_Harian!$B$8:$B$507,$A21,Sales_Harian!$Z$8:$Z$507,"Dikirim")+COUNTIFS(SPV_Harian!$A$8:$A$507,$B$4,SPV_Harian!$B$8:$B$507,$A21,SPV_Harian!$Y$8:$Y$507,"Dikirim")+COUNTIFS(ASM_Harian!$A$8:$A$507,$B$4,ASM_Harian!$B$8:$B$507,$A21,ASM_Harian!$Y$8:$Y$507,"Dikirim")=1,"Dikirim","Draft")))) -> Belum Lapor | H21: =IF(OR($A21="",F21=0),"",SUMIFS(Sales_Harian!$AF$8:$AF$507,Sales_Harian!$A$8:$A$507,$B$4,Sales_Harian!$B$8:$B$507,$A21)+SUMIFS(SPV_Harian!$AE$8:$AE$507,SPV_Harian!$A$8:$A$507,$B$4,SPV_Harian!$B$8:$B$507,$A21)+SUMIFS(ASM_Harian!$AE$8:$AE$507,ASM_Harian!$A$8:$A$507,$B$4,ASM_Harian!$B$8:$B$507,$A21)) | I21: =IF(OR($A21="",F21=0),"",SUMIFS(Sales_Harian!$AG$8:$AG$507,Sales_Harian!$A$8:$A$507,$B$4,Sales_Harian!$B$8:$B$507,$A21)+SUMIFS(SPV_Harian!$AF$8:$AF$507,SPV_Harian!$A$8:$A$507,$B$4,SPV_Harian!$B$8:$B$507,$A21)+SUMIFS(ASM_Harian!$AF$8:$AF$507,ASM_Harian!$A$8:$A$507,$B$4,ASM_Harian!$B$8:$B$507,$A21)) | J21: =IF(OR($A21="",F21=0),"",SUMIFS(Sales_Harian!$AH$8:$AH$507,Sales_Harian!$A$8:$A$507,$B$4,Sales_Harian!$B$8:$B$507,$A21)+SUMIFS(SPV_Harian!$AG$8:$AG$507,SPV_Harian!$A$8:$A$507,$B$4,SPV_Harian!$B$8:$B$507,$A21)+SUMIFS(ASM_Harian!$AG$8:$AG$507,ASM_Harian!$A$8:$A$507,$B$4,ASM_Harian!$B$8:$B$507,$A21)) | K21: =IF(OR($A21="",F21=0),"",SUMIFS(Sales_Harian!$AI$8:$AI$507,Sales_Harian!$A$8:$A$507,$B$4,Sales_Harian!$B$8:$B$507,$A21)+SUMIFS(SPV_Harian!$AH$8:$AH$507,SPV_Harian!$A$8:$A$507,$B$4,SPV_Harian!$B$8:$B$507,$A21)+SUMIFS(ASM_Harian!$AH$8:$AH$507,ASM_Harian!$A$8:$A$507,$B$4,ASM_Harian!$B$8:$B$507,$A21)) | L21: =IF(OR($A21="",F21=0),"",SUMIFS(Sales_Harian!$AK$8:$AK$507,Sales_Harian!$A$8:$A$507,$B$4,Sales_Harian!$B$8:$B$507,$A21)+SUMIFS(SPV_Harian!$AJ$8:$AJ$507,SPV_Harian!$A$8:$A$507,$B$4,SPV_Harian!$B$8:$B$507,$A21)+SUMIFS(ASM_Harian!$AJ$8:$AJ$507,ASM_Harian!$A$8:$A$507,$B$4,ASM_Harian!$B$8:$B$507,$A21)) | M21: =IF($A21="","",IF(OR(F21<>1,H21=0),"n.a.",I21/H21)) -> n.a. | N21: =IF($A21="","",IF(G21<>"Dikirim","",IF(COUNTIFS(Sales_Harian!$A$8:$A$507,$B$4,Sales_Harian!$B$8:$B$507,$A21,Sales_Harian!$AB$8:$AB$507,"Disetujui")+COUNTIFS(SPV_Harian!$A$8:$A$507,$B$4,SPV_Harian!$B$8:$B$507,$A21,SPV_Harian!$AA$8:$AA$507,"Disetujui")+COUNTIFS(ASM_Harian!$A$8:$A$507,$B$4,ASM_Harian!$B$8:$B$507,$A21,ASM_Harian!$AA$8:$AA$507,"Disetujui")=1,IF(COUNTIFS(Sales_Harian!$A$8:$A$507,$B$4,Sales_Harian!$B$8:$B$507,$A21,Sales_Harian!$AM$8:$AM$507,"<>OK")+COUNTIFS(SPV_Harian!$A$8:$A$507,$B$4,SPV_Harian!$B$8:$B$507,$A21,SPV_Harian!$AL$8:$AL$507,"<>OK")+COUNTIFS(ASM_Harian!$A$8:$A$507,$B$4,ASM_Harian!$B$8:$B$507,$A21,ASM_Harian!$AL$8:$AL$507,"<>OK")>0,"Review belum valid","Disetujui"),IF(COUNTIFS(Sales_Harian!$A$8:$A$507,$B$4,Sales_Harian!$B$8:$B$507,$A21,Sales_Harian!$AB$8:$AB$507,"Perlu Perbaikan")+COUNTIFS(SPV_Harian!$A$8:$A$507,$B$4,SPV_Harian!$B$8:$B$507,$A21,SPV_Harian!$AA$8:$AA$507,"Perlu Perbaikan")+COUNTIFS(ASM_Harian!$A$8:$A$507,$B$4,ASM_Harian!$B$8:$B$507,$A21,ASM_Harian!$AA$8:$AA$507,"Perlu Perbaikan")=1,"Perlu Perbaikan","Belum Diperiksa")))) | O21: =IF($A21="","",IF(F21=0,"Belum ada laporan",IF(F21>1,"Hapus/benahi laporan ganda",IF(COUNTIFS(Sales_Harian!$A$8:$A$507,$B$4,Sales_Harian!$B$8:$B$507,$A21,Sales_Harian!$AM$8:$AM$507,"<>OK")+COUNTIFS(SPV_Harian!$A$8:$A$507,$B$4,SPV_Harian!$B$8:$B$507,$A21,SPV_Harian!$AL$8:$AL$507,"<>OK")+COUNTIFS(ASM_Harian!$A$8:$A$507,$B$4,ASM_Harian!$B$8:$B$507,$A21,ASM_Harian!$AL$8:$AL$507,"<>OK")>0,"Periksa validasi_data",IF(SUM(J21:K21)>0,"Ada kegiatan terbuka",IF(N21="Perlu Perbaikan","Tindak lanjuti review",IF(G21="Draft","Kirim laporan",IF(N21="Belum Diperiksa","Menunggu pemeriksaan","")))))))) -> Belum ada laporan
A22: =IF(AND(Master_PIC!A9<>"",Master_PIC!G9="Aktif",Master_PIC!C9<>"Manager"),Master_PIC!A9,"") -> ASM01 | B22: =IF($A22="","",IF(Master_PIC!B9="","",Master_PIC!B9)) -> Teriyadi | C22: =IF($A22="","",IF(Master_PIC!C9="","",Master_PIC!C9)) -> ASM | D22: =IF($A22="","",IF(Master_PIC!D9="","",Master_PIC!D9)) -> Cirebon 1 (Lokal) | E22: =IF($A22="","",IF(Master_PIC!E9="","",Master_PIC!E9)) -> Timur | F22: =IF($A22="","",COUNTIFS(Sales_Harian!$A$8:$A$507,$B$4,Sales_Harian!$B$8:$B$507,$A22)+COUNTIFS(SPV_Harian!$A$8:$A$507,$B$4,SPV_Harian!$B$8:$B$507,$A22)+COUNTIFS(ASM_Harian!$A$8:$A$507,$B$4,ASM_Harian!$B$8:$B$507,$A22)) -> 0 | G22: =IF($A22="","",IF(F22=0,"Belum Lapor",IF(F22>1,"Data Ganda",IF(COUNTIFS(Sales_Harian!$A$8:$A$507,$B$4,Sales_Harian!$B$8:$B$507,$A22,Sales_Harian!$Z$8:$Z$507,"Dikirim")+COUNTIFS(SPV_Harian!$A$8:$A$507,$B$4,SPV_Harian!$B$8:$B$507,$A22,SPV_Harian!$Y$8:$Y$507,"Dikirim")+COUNTIFS(ASM_Harian!$A$8:$A$507,$B$4,ASM_Harian!$B$8:$B$507,$A22,ASM_Harian!$Y$8:$Y$507,"Dikirim")=1,"Dikirim","Draft")))) -> Belum Lapor | H22: =IF(OR($A22="",F22=0),"",SUMIFS(Sales_Harian!$AF$8:$AF$507,Sales_Harian!$A$8:$A$507,$B$4,Sales_Harian!$B$8:$B$507,$A22)+SUMIFS(SPV_Harian!$AE$8:$AE$507,SPV_Harian!$A$8:$A$507,$B$4,SPV_Harian!$B$8:$B$507,$A22)+SUMIFS(ASM_Harian!$AE$8:$AE$507,ASM_Harian!$A$8:$A$507,$B$4,ASM_Harian!$B$8:$B$507,$A22)) | I22: =IF(OR($A22="",F22=0),"",SUMIFS(Sales_Harian!$AG$8:$AG$507,Sales_Harian!$A$8:$A$507,$B$4,Sales_Harian!$B$8:$B$507,$A22)+SUMIFS(SPV_Harian!$AF$8:$AF$507,SPV_Harian!$A$8:$A$507,$B$4,SPV_Harian!$B$8:$B$507,$A22)+SUMIFS(ASM_Harian!$AF$8:$AF$507,ASM_Harian!$A$8:$A$507,$B$4,ASM_Harian!$B$8:$B$507,$A22)) | J22: =IF(OR($A22="",F22=0),"",SUMIFS(Sales_Harian!$AH$8:$AH$507,Sales_Harian!$A$8:$A$507,$B$4,Sales_Harian!$B$8:$B$507,$A22)+SUMIFS(SPV_Harian!$AG$8:$AG$507,SPV_Harian!$A$8:$A$507,$B$4,SPV_Harian!$B$8:$B$507,$A22)+SUMIFS(ASM_Harian!$AG$8:$AG$507,ASM_Harian!$A$8:$A$507,$B$4,ASM_Harian!$B$8:$B$507,$A22)) | K22: =IF(OR($A22="",F22=0),"",SUMIFS(Sales_Harian!$AI$8:$AI$507,Sales_Harian!$A$8:$A$507,$B$4,Sales_Harian!$B$8:$B$507,$A22)+SUMIFS(SPV_Harian!$AH$8:$AH$507,SPV_Harian!$A$8:$A$507,$B$4,SPV_Harian!$B$8:$B$507,$A22)+SUMIFS(ASM_Harian!$AH$8:$AH$507,ASM_Harian!$A$8:$A$507,$B$4,ASM_Harian!$B$8:$B$507,$A22)) | L22: =IF(OR($A22="",F22=0),"",SUMIFS(Sales_Harian!$AK$8:$AK$507,Sales_Harian!$A$8:$A$507,$B$4,Sales_Harian!$B$8:$B$507,$A22)+SUMIFS(SPV_Harian!$AJ$8:$AJ$507,SPV_Harian!$A$8:$A$507,$B$4,SPV_Harian!$B$8:$B$507,$A22)+SUMIFS(ASM_Harian!$AJ$8:$AJ$507,ASM_Harian!$A$8:$A$507,$B$4,ASM_Harian!$B$8:$B$507,$A22)) | M22: =IF($A22="","",IF(OR(F22<>1,H22=0),"n.a.",I22/H22)) -> n.a. | N22: =IF($A22="","",IF(G22<>"Dikirim","",IF(COUNTIFS(Sales_Harian!$A$8:$A$507,$B$4,Sales_Harian!$B$8:$B$507,$A22,Sales_Harian!$AB$8:$AB$507,"Disetujui")+COUNTIFS(SPV_Harian!$A$8:$A$507,$B$4,SPV_Harian!$B$8:$B$507,$A22,SPV_Harian!$AA$8:$AA$507,"Disetujui")+COUNTIFS(ASM_Harian!$A$8:$A$507,$B$4,ASM_Harian!$B$8:$B$507,$A22,ASM_Harian!$AA$8:$AA$507,"Disetujui")=1,IF(COUNTIFS(Sales_Harian!$A$8:$A$507,$B$4,Sales_Harian!$B$8:$B$507,$A22,Sales_Harian!$AM$8:$AM$507,"<>OK")+COUNTIFS(SPV_Harian!$A$8:$A$507,$B$4,SPV_Harian!$B$8:$B$507,$A22,SPV_Harian!$AL$8:$AL$507,"<>OK")+COUNTIFS(ASM_Harian!$A$8:$A$507,$B$4,ASM_Harian!$B$8:$B$507,$A22,ASM_Harian!$AL$8:$AL$507,"<>OK")>0,"Review belum valid","Disetujui"),IF(COUNTIFS(Sales_Harian!$A$8:$A$507,$B$4,Sales_Harian!$B$8:$B$507,$A22,Sales_Harian!$AB$8:$AB$507,"Perlu Perbaikan")+COUNTIFS(SPV_Harian!$A$8:$A$507,$B$4,SPV_Harian!$B$8:$B$507,$A22,SPV_Harian!$AA$8:$AA$507,"Perlu Perbaikan")+COUNTIFS(ASM_Harian!$A$8:$A$507,$B$4,ASM_Harian!$B$8:$B$507,$A22,ASM_Harian!$AA$8:$AA$507,"Perlu Perbaikan")=1,"Perlu Perbaikan","Belum Diperiksa")))) | O22: =IF($A22="","",IF(F22=0,"Belum ada laporan",IF(F22>1,"Hapus/benahi laporan ganda",IF(COUNTIFS(Sales_Harian!$A$8:$A$507,$B$4,Sales_Harian!$B$8:$B$507,$A22,Sales_Harian!$AM$8:$AM$507,"<>OK")+COUNTIFS(SPV_Harian!$A$8:$A$507,$B$4,SPV_Harian!$B$8:$B$507,$A22,SPV_Harian!$AL$8:$AL$507,"<>OK")+COUNTIFS(ASM_Harian!$A$8:$A$507,$B$4,ASM_Harian!$B$8:$B$507,$A22,ASM_Harian!$AL$8:$AL$507,"<>OK")>0,"Periksa validasi_data",IF(SUM(J22:K22)>0,"Ada kegiatan terbuka",IF(N22="Perlu Perbaikan","Tindak lanjuti review",IF(G22="Draft","Kirim laporan",IF(N22="Belum Diperiksa","Menunggu pemeriksaan","")))))))) -> Belum ada laporan
A23: =IF(AND(Master_PIC!A8<>"",Master_PIC!G8="Aktif",Master_PIC!C8<>"Manager"),Master_PIC!A8,"") | B23: =IF($A23="","",IF(Master_PIC!B8="","",Master_PIC!B8)) | C23: =IF($A23="","",IF(Master_PIC!C8="","",Master_PIC!C8)) | D23: =IF($A23="","",IF(Master_PIC!D8="","",Master_PIC!D8)) | E23: =IF($A23="","",IF(Master_PIC!E8="","",Master_PIC!E8)) | F23: =IF($A23="","",COUNTIFS(Sales_Harian!$A$8:$A$507,$B$4,Sales_Harian!$B$8:$B$507,$A23)+COUNTIFS(SPV_Harian!$A$8:$A$507,$B$4,SPV_Harian!$B$8:$B$507,$A23)+COUNTIFS(ASM_Harian!$A$8:$A$507,$B$4,ASM_Harian!$B$8:$B$507,$A23)) | G23: =IF($A23="","",IF(F23=0,"Belum Lapor",IF(F23>1,"Data Ganda",IF(COUNTIFS(Sales_Harian!$A$8:$A$507,$B$4,Sales_Harian!$B$8:$B$507,$A23,Sales_Harian!$Z$8:$Z$507,"Dikirim")+COUNTIFS(SPV_Harian!$A$8:$A$507,$B$4,SPV_Harian!$B$8:$B$507,$A23,SPV_Harian!$Y$8:$Y$507,"Dikirim")+COUNTIFS(ASM_Harian!$A$8:$A$507,$B$4,ASM_Harian!$B$8:$B$507,$A23,ASM_Harian!$Y$8:$Y$507,"Dikirim")=1,"Dikirim","Draft")))) | H23: =IF(OR($A23="",F23=0),"",SUMIFS(Sales_Harian!$AF$8:$AF$507,Sales_Harian!$A$8:$A$507,$B$4,Sales_Harian!$B$8:$B$507,$A23)+SUMIFS(SPV_Harian!$AE$8:$AE$507,SPV_Harian!$A$8:$A$507,$B$4,SPV_Harian!$B$8:$B$507,$A23)+SUMIFS(ASM_Harian!$AE$8:$AE$507,ASM_Harian!$A$8:$A$507,$B$4,ASM_Harian!$B$8:$B$507,$A23)) | I23: =IF(OR($A23="",F23=0),"",SUMIFS(Sales_Harian!$AG$8:$AG$507,Sales_Harian!$A$8:$A$507,$B$4,Sales_Harian!$B$8:$B$507,$A23)+SUMIFS(SPV_Harian!$AF$8:$AF$507,SPV_Harian!$A$8:$A$507,$B$4,SPV_Harian!$B$8:$B$507,$A23)+SUMIFS(ASM_Harian!$AF$8:$AF$507,ASM_Harian!$A$8:$A$507,$B$4,ASM_Harian!$B$8:$B$507,$A23)) | J23: =IF(OR($A23="",F23=0),"",SUMIFS(Sales_Harian!$AH$8:$AH$507,Sales_Harian!$A$8:$A$507,$B$4,Sales_Harian!$B$8:$B$507,$A23)+SUMIFS(SPV_Harian!$AG$8:$AG$507,SPV_Harian!$A$8:$A$507,$B$4,SPV_Harian!$B$8:$B$507,$A23)+SUMIFS(ASM_Harian!$AG$8:$AG$507,ASM_Harian!$A$8:$A$507,$B$4,ASM_Harian!$B$8:$B$507,$A23)) | K23: =IF(OR($A23="",F23=0),"",SUMIFS(Sales_Harian!$AI$8:$AI$507,Sales_Harian!$A$8:$A$507,$B$4,Sales_Harian!$B$8:$B$507,$A23)+SUMIFS(SPV_Harian!$AH$8:$AH$507,SPV_Harian!$A$8:$A$507,$B$4,SPV_Harian!$B$8:$B$507,$A23)+SUMIFS(ASM_Harian!$AH$8:$AH$507,ASM_Harian!$A$8:$A$507,$B$4,ASM_Harian!$B$8:$B$507,$A23)) | L23: =IF(OR($A23="",F23=0),"",SUMIFS(Sales_Harian!$AK$8:$AK$507,Sales_Harian!$A$8:$A$507,$B$4,Sales_Harian!$B$8:$B$507,$A23)+SUMIFS(SPV_Harian!$AJ$8:$AJ$507,SPV_Harian!$A$8:$A$507,$B$4,SPV_Harian!$B$8:$B$507,$A23)+SUMIFS(ASM_Harian!$AJ$8:$AJ$507,ASM_Harian!$A$8:$A$507,$B$4,ASM_Harian!$B$8:$B$507,$A23)) | M23: =IF($A23="","",IF(OR(F23<>1,H23=0),"n.a.",I23/H23)) | N23: =IF($A23="","",IF(G23<>"Dikirim","",IF(COUNTIFS(Sales_Harian!$A$8:$A$507,$B$4,Sales_Harian!$B$8:$B$507,$A23,Sales_Harian!$AB$8:$AB$507,"Disetujui")+COUNTIFS(SPV_Harian!$A$8:$A$507,$B$4,SPV_Harian!$B$8:$B$507,$A23,SPV_Harian!$AA$8:$AA$507,"Disetujui")+COUNTIFS(ASM_Harian!$A$8:$A$507,$B$4,ASM_Harian!$B$8:$B$507,$A23,ASM_Harian!$AA$8:$AA$507,"Disetujui")=1,IF(COUNTIFS(Sales_Harian!$A$8:$A$507,$B$4,Sales_Harian!$B$8:$B$507,$A23,Sales_Harian!$AM$8:$AM$507,"<>OK")+COUNTIFS(SPV_Harian!$A$8:$A$507,$B$4,SPV_Harian!$B$8:$B$507,$A23,SPV_Harian!$AL$8:$AL$507,"<>OK")+COUNTIFS(ASM_Harian!$A$8:$A$507,$B$4,ASM_Harian!$B$8:$B$507,$A23,ASM_Harian!$AL$8:$AL$507,"<>OK")>0,"Review belum valid","Disetujui"),IF(COUNTIFS(Sales_Harian!$A$8:$A$507,$B$4,Sales_Harian!$B$8:$B$507,$A23,Sales_Harian!$AB$8:$AB$507,"Perlu Perbaikan")+COUNTIFS(SPV_Harian!$A$8:$A$507,$B$4,SPV_Harian!$B$8:$B$507,$A23,SPV_Harian!$AA$8:$AA$507,"Perlu Perbaikan")+COUNTIFS(ASM_Harian!$A$8:$A$507,$B$4,ASM_Harian!$B$8:$B$507,$A23,ASM_Harian!$AA$8:$AA$507,"Perlu Perbaikan")=1,"Perlu Perbaikan","Belum Diperiksa")))) | O23: =IF($A23="","",IF(F23=0,"Belum ada laporan",IF(F23>1,"Hapus/benahi laporan ganda",IF(COUNTIFS(Sales_Harian!$A$8:$A$507,$B$4,Sales_Harian!$B$8:$B$507,$A23,Sales_Harian!$AM$8:$AM$507,"<>OK")+COUNTIFS(SPV_Harian!$A$8:$A$507,$B$4,SPV_Harian!$B$8:$B$507,$A23,SPV_Harian!$AL$8:$AL$507,"<>OK")+COUNTIFS(ASM_Harian!$A$8:$A$507,$B$4,ASM_Harian!$B$8:$B$507,$A23,ASM_Harian!$AL$8:$AL$507,"<>OK")>0,"Periksa validasi_data",IF(SUM(J23:K23)>0,"Ada kegiatan terbuka",IF(N23="Perlu Perbaikan","Tindak lanjuti review",IF(G23="Draft","Kirim laporan",IF(N23="Belum Diperiksa","Menunggu pemeriksaan",""))))))))
A24: =IF(AND(Master_PIC!A13<>"",Master_PIC!G13="Aktif",Master_PIC!C13<>"Manager"),Master_PIC!A13,"") -> Sales02 | B24: =IF($A24="","",IF(Master_PIC!B13="","",Master_PIC!B13)) -> Syarfi Hermana | C24: =IF($A24="","",IF(Master_PIC!C13="","",Master_PIC!C13)) -> Sales | D24: =IF($A24="","",IF(Master_PIC!D13="","",Master_PIC!D13)) -> Cirebon 1 (Lokal) | E24: =IF($A24="","",IF(Master_PIC!E13="","",Master_PIC!E13)) -> Timur | F24: =IF($A24="","",COUNTIFS(Sales_Harian!$A$8:$A$507,$B$4,Sales_Harian!$B$8:$B$507,$A24)+COUNTIFS(SPV_Harian!$A$8:$A$507,$B$4,SPV_Harian!$B$8:$B$507,$A24)+COUNTIFS(ASM_Harian!$A$8:$A$507,$B$4,ASM_Harian!$B$8:$B$507,$A24)) -> 0 | G24: =IF($A24="","",IF(F24=0,"Belum Lapor",IF(F24>1,"Data Ganda",IF(COUNTIFS(Sales_Harian!$A$8:$A$507,$B$4,Sales_Harian!$B$8:$B$507,$A24,Sales_Harian!$Z$8:$Z$507,"Dikirim")+COUNTIFS(SPV_Harian!$A$8:$A$507,$B$4,SPV_Harian!$B$8:$B$507,$A24,SPV_Harian!$Y$8:$Y$507,"Dikirim")+COUNTIFS(ASM_Harian!$A$8:$A$507,$B$4,ASM_Harian!$B$8:$B$507,$A24,ASM_Harian!$Y$8:$Y$507,"Dikirim")=1,"Dikirim","Draft")))) -> Belum Lapor | H24: =IF(OR($A24="",F24=0),"",SUMIFS(Sales_Harian!$AF$8:$AF$507,Sales_Harian!$A$8:$A$507,$B$4,Sales_Harian!$B$8:$B$507,$A24)+SUMIFS(SPV_Harian!$AE$8:$AE$507,SPV_Harian!$A$8:$A$507,$B$4,SPV_Harian!$B$8:$B$507,$A24)+SUMIFS(ASM_Harian!$AE$8:$AE$507,ASM_Harian!$A$8:$A$507,$B$4,ASM_Harian!$B$8:$B$507,$A24)) | I24: =IF(OR($A24="",F24=0),"",SUMIFS(Sales_Harian!$AG$8:$AG$507,Sales_Harian!$A$8:$A$507,$B$4,Sales_Harian!$B$8:$B$507,$A24)+SUMIFS(SPV_Harian!$AF$8:$AF$507,SPV_Harian!$A$8:$A$507,$B$4,SPV_Harian!$B$8:$B$507,$A24)+SUMIFS(ASM_Harian!$AF$8:$AF$507,ASM_Harian!$A$8:$A$507,$B$4,ASM_Harian!$B$8:$B$507,$A24)) | J24: =IF(OR($A24="",F24=0),"",SUMIFS(Sales_Harian!$AH$8:$AH$507,Sales_Harian!$A$8:$A$507,$B$4,Sales_Harian!$B$8:$B$507,$A24)+SUMIFS(SPV_Harian!$AG$8:$AG$507,SPV_Harian!$A$8:$A$507,$B$4,SPV_Harian!$B$8:$B$507,$A24)+SUMIFS(ASM_Harian!$AG$8:$AG$507,ASM_Harian!$A$8:$A$507,$B$4,ASM_Harian!$B$8:$B$507,$A24)) | K24: =IF(OR($A24="",F24=0),"",SUMIFS(Sales_Harian!$AI$8:$AI$507,Sales_Harian!$A$8:$A$507,$B$4,Sales_Harian!$B$8:$B$507,$A24)+SUMIFS(SPV_Harian!$AH$8:$AH$507,SPV_Harian!$A$8:$A$507,$B$4,SPV_Harian!$B$8:$B$507,$A24)+SUMIFS(ASM_Harian!$AH$8:$AH$507,ASM_Harian!$A$8:$A$507,$B$4,ASM_Harian!$B$8:$B$507,$A24)) | L24: =IF(OR($A24="",F24=0),"",SUMIFS(Sales_Harian!$AK$8:$AK$507,Sales_Harian!$A$8:$A$507,$B$4,Sales_Harian!$B$8:$B$507,$A24)+SUMIFS(SPV_Harian!$AJ$8:$AJ$507,SPV_Harian!$A$8:$A$507,$B$4,SPV_Harian!$B$8:$B$507,$A24)+SUMIFS(ASM_Harian!$AJ$8:$AJ$507,ASM_Harian!$A$8:$A$507,$B$4,ASM_Harian!$B$8:$B$507,$A24)) | M24: =IF($A24="","",IF(OR(F24<>1,H24=0),"n.a.",I24/H24)) -> n.a. | N24: =IF($A24="","",IF(G24<>"Dikirim","",IF(COUNTIFS(Sales_Harian!$A$8:$A$507,$B$4,Sales_Harian!$B$8:$B$507,$A24,Sales_Harian!$AB$8:$AB$507,"Disetujui")+COUNTIFS(SPV_Harian!$A$8:$A$507,$B$4,SPV_Harian!$B$8:$B$507,$A24,SPV_Harian!$AA$8:$AA$507,"Disetujui")+COUNTIFS(ASM_Harian!$A$8:$A$507,$B$4,ASM_Harian!$B$8:$B$507,$A24,ASM_Harian!$AA$8:$AA$507,"Disetujui")=1,IF(COUNTIFS(Sales_Harian!$A$8:$A$507,$B$4,Sales_Harian!$B$8:$B$507,$A24,Sales_Harian!$AM$8:$AM$507,"<>OK")+COUNTIFS(SPV_Harian!$A$8:$A$507,$B$4,SPV_Harian!$B$8:$B$507,$A24,SPV_Harian!$AL$8:$AL$507,"<>OK")+COUNTIFS(ASM_Harian!$A$8:$A$507,$B$4,ASM_Harian!$B$8:$B$507,$A24,ASM_Harian!$AL$8:$AL$507,"<>OK")>0,"Review belum valid","Disetujui"),IF(COUNTIFS(Sales_Harian!$A$8:$A$507,$B$4,Sales_Harian!$B$8:$B$507,$A24,Sales_Harian!$AB$8:$AB$507,"Perlu Perbaikan")+COUNTIFS(SPV_Harian!$A$8:$A$507,$B$4,SPV_Harian!$B$8:$B$507,$A24,SPV_Harian!$AA$8:$AA$507,"Perlu Perbaikan")+COUNTIFS(ASM_Harian!$A$8:$A$507,$B$4,ASM_Harian!$B$8:$B$507,$A24,ASM_Harian!$AA$8:$AA$507,"Perlu Perbaikan")=1,"Perlu Perbaikan","Belum Diperiksa")))) | O24: =IF($A24="","",IF(F24=0,"Belum ada laporan",IF(F24>1,"Hapus/benahi laporan ganda",IF(COUNTIFS(Sales_Harian!$A$8:$A$507,$B$4,Sales_Harian!$B$8:$B$507,$A24,Sales_Harian!$AM$8:$AM$507,"<>OK")+COUNTIFS(SPV_Harian!$A$8:$A$507,$B$4,SPV_Harian!$B$8:$B$507,$A24,SPV_Harian!$AL$8:$AL$507,"<>OK")+COUNTIFS(ASM_Harian!$A$8:$A$507,$B$4,ASM_Harian!$B$8:$B$507,$A24,ASM_Harian!$AL$8:$AL$507,"<>OK")>0,"Periksa validasi_data",IF(SUM(J24:K24)>0,"Ada kegiatan terbuka",IF(N24="Perlu Perbaikan","Tindak lanjuti review",IF(G24="Draft","Kirim laporan",IF(N24="Belum Diperiksa","Menunggu pemeriksaan","")))))))) -> Belum ada laporan
A25: =IF(AND(Master_PIC!A14<>"",Master_PIC!G14="Aktif",Master_PIC!C14<>"Manager"),Master_PIC!A14,"") -> Sales03 | B25: =IF($A25="","",IF(Master_PIC!B14="","",Master_PIC!B14)) -> Toto Toharudin | C25: =IF($A25="","",IF(Master_PIC!C14="","",Master_PIC!C14)) -> Sales | D25: =IF($A25="","",IF(Master_PIC!D14="","",Master_PIC!D14)) -> Cirebon 1 (Lokal) | E25: =IF($A25="","",IF(Master_PIC!E14="","",Master_PIC!E14)) -> Timur | F25: =IF($A25="","",COUNTIFS(Sales_Harian!$A$8:$A$507,$B$4,Sales_Harian!$B$8:$B$507,$A25)+COUNTIFS(SPV_Harian!$A$8:$A$507,$B$4,SPV_Harian!$B$8:$B$507,$A25)+COUNTIFS(ASM_Harian!$A$8:$A$507,$B$4,ASM_Harian!$B$8:$B$507,$A25)) -> 0 | G25: =IF($A25="","",IF(F25=0,"Belum Lapor",IF(F25>1,"Data Ganda",IF(COUNTIFS(Sales_Harian!$A$8:$A$507,$B$4,Sales_Harian!$B$8:$B$507,$A25,Sales_Harian!$Z$8:$Z$507,"Dikirim")+COUNTIFS(SPV_Harian!$A$8:$A$507,$B$4,SPV_Harian!$B$8:$B$507,$A25,SPV_Harian!$Y$8:$Y$507,"Dikirim")+COUNTIFS(ASM_Harian!$A$8:$A$507,$B$4,ASM_Harian!$B$8:$B$507,$A25,ASM_Harian!$Y$8:$Y$507,"Dikirim")=1,"Dikirim","Draft")))) -> Belum Lapor | H25: =IF(OR($A25="",F25=0),"",SUMIFS(Sales_Harian!$AF$8:$AF$507,Sales_Harian!$A$8:$A$507,$B$4,Sales_Harian!$B$8:$B$507,$A25)+SUMIFS(SPV_Harian!$AE$8:$AE$507,SPV_Harian!$A$8:$A$507,$B$4,SPV_Harian!$B$8:$B$507,$A25)+SUMIFS(ASM_Harian!$AE$8:$AE$507,ASM_Harian!$A$8:$A$507,$B$4,ASM_Harian!$B$8:$B$507,$A25)) | I25: =IF(OR($A25="",F25=0),"",SUMIFS(Sales_Harian!$AG$8:$AG$507,Sales_Harian!$A$8:$A$507,$B$4,Sales_Harian!$B$8:$B$507,$A25)+SUMIFS(SPV_Harian!$AF$8:$AF$507,SPV_Harian!$A$8:$A$507,$B$4,SPV_Harian!$B$8:$B$507,$A25)+SUMIFS(ASM_Harian!$AF$8:$AF$507,ASM_Harian!$A$8:$A$507,$B$4,ASM_Harian!$B$8:$B$507,$A25)) | J25: =IF(OR($A25="",F25=0),"",SUMIFS(Sales_Harian!$AH$8:$AH$507,Sales_Harian!$A$8:$A$507,$B$4,Sales_Harian!$B$8:$B$507,$A25)+SUMIFS(SPV_Harian!$AG$8:$AG$507,SPV_Harian!$A$8:$A$507,$B$4,SPV_Harian!$B$8:$B$507,$A25)+SUMIFS(ASM_Harian!$AG$8:$AG$507,ASM_Harian!$A$8:$A$507,$B$4,ASM_Harian!$B$8:$B$507,$A25)) | K25: =IF(OR($A25="",F25=0),"",SUMIFS(Sales_Harian!$AI$8:$AI$507,Sales_Harian!$A$8:$A$507,$B$4,Sales_Harian!$B$8:$B$507,$A25)+SUMIFS(SPV_Harian!$AH$8:$AH$507,SPV_Harian!$A$8:$A$507,$B$4,SPV_Harian!$B$8:$B$507,$A25)+SUMIFS(ASM_Harian!$AH$8:$AH$507,ASM_Harian!$A$8:$A$507,$B$4,ASM_Harian!$B$8:$B$507,$A25)) | L25: =IF(OR($A25="",F25=0),"",SUMIFS(Sales_Harian!$AK$8:$AK$507,Sales_Harian!$A$8:$A$507,$B$4,Sales_Harian!$B$8:$B$507,$A25)+SUMIFS(SPV_Harian!$AJ$8:$AJ$507,SPV_Harian!$A$8:$A$507,$B$4,SPV_Harian!$B$8:$B$507,$A25)+SUMIFS(ASM_Harian!$AJ$8:$AJ$507,ASM_Harian!$A$8:$A$507,$B$4,ASM_Harian!$B$8:$B$507,$A25)) | M25: =IF($A25="","",IF(OR(F25<>1,H25=0),"n.a.",I25/H25)) -> n.a. | N25: =IF($A25="","",IF(G25<>"Dikirim","",IF(COUNTIFS(Sales_Harian!$A$8:$A$507,$B$4,Sales_Harian!$B$8:$B$507,$A25,Sales_Harian!$AB$8:$AB$507,"Disetujui")+COUNTIFS(SPV_Harian!$A$8:$A$507,$B$4,SPV_Harian!$B$8:$B$507,$A25,SPV_Harian!$AA$8:$AA$507,"Disetujui")+COUNTIFS(ASM_Harian!$A$8:$A$507,$B$4,ASM_Harian!$B$8:$B$507,$A25,ASM_Harian!$AA$8:$AA$507,"Disetujui")=1,IF(COUNTIFS(Sales_Harian!$A$8:$A$507,$B$4,Sales_Harian!$B$8:$B$507,$A25,Sales_Harian!$AM$8:$AM$507,"<>OK")+COUNTIFS(SPV_Harian!$A$8:$A$507,$B$4,SPV_Harian!$B$8:$B$507,$A25,SPV_Harian!$AL$8:$AL$507,"<>OK")+COUNTIFS(ASM_Harian!$A$8:$A$507,$B$4,ASM_Harian!$B$8:$B$507,$A25,ASM_Harian!$AL$8:$AL$507,"<>OK")>0,"Review belum valid","Disetujui"),IF(COUNTIFS(Sales_Harian!$A$8:$A$507,$B$4,Sales_Harian!$B$8:$B$507,$A25,Sales_Harian!$AB$8:$AB$507,"Perlu Perbaikan")+COUNTIFS(SPV_Harian!$A$8:$A$507,$B$4,SPV_Harian!$B$8:$B$507,$A25,SPV_Harian!$AA$8:$AA$507,"Perlu Perbaikan")+COUNTIFS(ASM_Harian!$A$8:$A$507,$B$4,ASM_Harian!$B$8:$B$507,$A25,ASM_Harian!$AA$8:$AA$507,"Perlu Perbaikan")=1,"Perlu Perbaikan","Belum Diperiksa")))) | O25: =IF($A25="","",IF(F25=0,"Belum ada laporan",IF(F25>1,"Hapus/benahi laporan ganda",IF(COUNTIFS(Sales_Harian!$A$8:$A$507,$B$4,Sales_Harian!$B$8:$B$507,$A25,Sales_Harian!$AM$8:$AM$507,"<>OK")+COUNTIFS(SPV_Harian!$A$8:$A$507,$B$4,SPV_Harian!$B$8:$B$507,$A25,SPV_Harian!$AL$8:$AL$507,"<>OK")+COUNTIFS(ASM_Harian!$A$8:$A$507,$B$4,ASM_Harian!$B$8:$B$507,$A25,ASM_Harian!$AL$8:$AL$507,"<>OK")>0,"Periksa validasi_data",IF(SUM(J25:K25)>0,"Ada kegiatan terbuka",IF(N25="Perlu Perbaikan","Tindak lanjuti review",IF(G25="Draft","Kirim laporan",IF(N25="Belum Diperiksa","Menunggu pemeriksaan","")))))))) -> Belum ada laporan
A26: =IF(AND(Master_PIC!A15<>"",Master_PIC!G15="Aktif",Master_PIC!C15<>"Manager"),Master_PIC!A15,"") -> Sales04 | B26: =IF($A26="","",IF(Master_PIC!B15="","",Master_PIC!B15)) -> Moh. Rahmadi Dwi Putra | C26: =IF($A26="","",IF(Master_PIC!C15="","",Master_PIC!C15)) -> Sales | D26: =IF($A26="","",IF(Master_PIC!D15="","",Master_PIC!D15)) -> Cirebon 1 (Lokal) | E26: =IF($A26="","",IF(Master_PIC!E15="","",Master_PIC!E15)) -> Timur | F26: =IF($A26="","",COUNTIFS(Sales_Harian!$A$8:$A$507,$B$4,Sales_Harian!$B$8:$B$507,$A26)+COUNTIFS(SPV_Harian!$A$8:$A$507,$B$4,SPV_Harian!$B$8:$B$507,$A26)+COUNTIFS(ASM_Harian!$A$8:$A$507,$B$4,ASM_Harian!$B$8:$B$507,$A26)) -> 0 | G26: =IF($A26="","",IF(F26=0,"Belum Lapor",IF(F26>1,"Data Ganda",IF(COUNTIFS(Sales_Harian!$A$8:$A$507,$B$4,Sales_Harian!$B$8:$B$507,$A26,Sales_Harian!$Z$8:$Z$507,"Dikirim")+COUNTIFS(SPV_Harian!$A$8:$A$507,$B$4,SPV_Harian!$B$8:$B$507,$A26,SPV_Harian!$Y$8:$Y$507,"Dikirim")+COUNTIFS(ASM_Harian!$A$8:$A$507,$B$4,ASM_Harian!$B$8:$B$507,$A26,ASM_Harian!$Y$8:$Y$507,"Dikirim")=1,"Dikirim","Draft")))) -> Belum Lapor | H26: =IF(OR($A26="",F26=0),"",SUMIFS(Sales_Harian!$AF$8:$AF$507,Sales_Harian!$A$8:$A$507,$B$4,Sales_Harian!$B$8:$B$507,$A26)+SUMIFS(SPV_Harian!$AE$8:$AE$507,SPV_Harian!$A$8:$A$507,$B$4,SPV_Harian!$B$8:$B$507,$A26)+SUMIFS(ASM_Harian!$AE$8:$AE$507,ASM_Harian!$A$8:$A$507,$B$4,ASM_Harian!$B$8:$B$507,$A26)) | I26: =IF(OR($A26="",F26=0),"",SUMIFS(Sales_Harian!$AG$8:$AG$507,Sales_Harian!$A$8:$A$507,$B$4,Sales_Harian!$B$8:$B$507,$A26)+SUMIFS(SPV_Harian!$AF$8:$AF$507,SPV_Harian!$A$8:$A$507,$B$4,SPV_Harian!$B$8:$B$507,$A26)+SUMIFS(ASM_Harian!$AF$8:$AF$507,ASM_Harian!$A$8:$A$507,$B$4,ASM_Harian!$B$8:$B$507,$A26)) | J26: =IF(OR($A26="",F26=0),"",SUMIFS(Sales_Harian!$AH$8:$AH$507,Sales_Harian!$A$8:$A$507,$B$4,Sales_Harian!$B$8:$B$507,$A26)+SUMIFS(SPV_Harian!$AG$8:$AG$507,SPV_Harian!$A$8:$A$507,$B$4,SPV_Harian!$B$8:$B$507,$A26)+SUMIFS(ASM_Harian!$AG$8:$AG$507,ASM_Harian!$A$8:$A$507,$B$4,ASM_Harian!$B$8:$B$507,$A26)) | K26: =IF(OR($A26="",F26=0),"",SUMIFS(Sales_Harian!$AI$8:$AI$507,Sales_Harian!$A$8:$A$507,$B$4,Sales_Harian!$B$8:$B$507,$A26)+SUMIFS(SPV_Harian!$AH$8:$AH$507,SPV_Harian!$A$8:$A$507,$B$4,SPV_Harian!$B$8:$B$507,$A26)+SUMIFS(ASM_Harian!$AH$8:$AH$507,ASM_Harian!$A$8:$A$507,$B$4,ASM_Harian!$B$8:$B$507,$A26)) | L26: =IF(OR($A26="",F26=0),"",SUMIFS(Sales_Harian!$AK$8:$AK$507,Sales_Harian!$A$8:$A$507,$B$4,Sales_Harian!$B$8:$B$507,$A26)+SUMIFS(SPV_Harian!$AJ$8:$AJ$507,SPV_Harian!$A$8:$A$507,$B$4,SPV_Harian!$B$8:$B$507,$A26)+SUMIFS(ASM_Harian!$AJ$8:$AJ$507,ASM_Harian!$A$8:$A$507,$B$4,ASM_Harian!$B$8:$B$507,$A26)) | M26: =IF($A26="","",IF(OR(F26<>1,H26=0),"n.a.",I26/H26)) -> n.a. | N26: =IF($A26="","",IF(G26<>"Dikirim","",IF(COUNTIFS(Sales_Harian!$A$8:$A$507,$B$4,Sales_Harian!$B$8:$B$507,$A26,Sales_Harian!$AB$8:$AB$507,"Disetujui")+COUNTIFS(SPV_Harian!$A$8:$A$507,$B$4,SPV_Harian!$B$8:$B$507,$A26,SPV_Harian!$AA$8:$AA$507,"Disetujui")+COUNTIFS(ASM_Harian!$A$8:$A$507,$B$4,ASM_Harian!$B$8:$B$507,$A26,ASM_Harian!$AA$8:$AA$507,"Disetujui")=1,IF(COUNTIFS(Sales_Harian!$A$8:$A$507,$B$4,Sales_Harian!$B$8:$B$507,$A26,Sales_Harian!$AM$8:$AM$507,"<>OK")+COUNTIFS(SPV_Harian!$A$8:$A$507,$B$4,SPV_Harian!$B$8:$B$507,$A26,SPV_Harian!$AL$8:$AL$507,"<>OK")+COUNTIFS(ASM_Harian!$A$8:$A$507,$B$4,ASM_Harian!$B$8:$B$507,$A26,ASM_Harian!$AL$8:$AL$507,"<>OK")>0,"Review belum valid","Disetujui"),IF(COUNTIFS(Sales_Harian!$A$8:$A$507,$B$4,Sales_Harian!$B$8:$B$507,$A26,Sales_Harian!$AB$8:$AB$507,"Perlu Perbaikan")+COUNTIFS(SPV_Harian!$A$8:$A$507,$B$4,SPV_Harian!$B$8:$B$507,$A26,SPV_Harian!$AA$8:$AA$507,"Perlu Perbaikan")+COUNTIFS(ASM_Harian!$A$8:$A$507,$B$4,ASM_Harian!$B$8:$B$507,$A26,ASM_Harian!$AA$8:$AA$507,"Perlu Perbaikan")=1,"Perlu Perbaikan","Belum Diperiksa")))) | O26: =IF($A26="","",IF(F26=0,"Belum ada laporan",IF(F26>1,"Hapus/benahi laporan ganda",IF(COUNTIFS(Sales_Harian!$A$8:$A$507,$B$4,Sales_Harian!$B$8:$B$507,$A26,Sales_Harian!$AM$8:$AM$507,"<>OK")+COUNTIFS(SPV_Harian!$A$8:$A$507,$B$4,SPV_Harian!$B$8:$B$507,$A26,SPV_Harian!$AL$8:$AL$507,"<>OK")+COUNTIFS(ASM_Harian!$A$8:$A$507,$B$4,ASM_Harian!$B$8:$B$507,$A26,ASM_Harian!$AL$8:$AL$507,"<>OK")>0,"Periksa validasi_data",IF(SUM(J26:K26)>0,"Ada kegiatan terbuka",IF(N26="Perlu Perbaikan","Tindak lanjuti review",IF(G26="Draft","Kirim laporan",IF(N26="Belum Diperiksa","Menunggu pemeriksaan","")))))))) -> Belum ada laporan
A27: =IF(AND(Master_PIC!A16<>"",Master_PIC!G16="Aktif",Master_PIC!C16<>"Manager"),Master_PIC!A16,"") -> Sales05 | B27: =IF($A27="","",IF(Master_PIC!B16="","",Master_PIC!B16)) -> Suherman SBFI | C27: =IF($A27="","",IF(Master_PIC!C16="","",Master_PIC!C16)) -> Sales | D27: =IF($A27="","",IF(Master_PIC!D16="","",Master_PIC!D16)) -> Cirebon 1 (Lokal) | E27: =IF($A27="","",IF(Master_PIC!E16="","",Master_PIC!E16)) -> Timur | F27: =IF($A27="","",COUNTIFS(Sales_Harian!$A$8:$A$507,$B$4,Sales_Harian!$B$8:$B$507,$A27)+COUNTIFS(SPV_Harian!$A$8:$A$507,$B$4,SPV_Harian!$B$8:$B$507,$A27)+COUNTIFS(ASM_Harian!$A$8:$A$507,$B$4,ASM_Harian!$B$8:$B$507,$A27)) -> 0 | G27: =IF($A27="","",IF(F27=0,"Belum Lapor",IF(F27>1,"Data Ganda",IF(COUNTIFS(Sales_Harian!$A$8:$A$507,$B$4,Sales_Harian!$B$8:$B$507,$A27,Sales_Harian!$Z$8:$Z$507,"Dikirim")+COUNTIFS(SPV_Harian!$A$8:$A$507,$B$4,SPV_Harian!$B$8:$B$507,$A27,SPV_Harian!$Y$8:$Y$507,"Dikirim")+COUNTIFS(ASM_Harian!$A$8:$A$507,$B$4,ASM_Harian!$B$8:$B$507,$A27,ASM_Harian!$Y$8:$Y$507,"Dikirim")=1,"Dikirim","Draft")))) -> Belum Lapor | H27: =IF(OR($A27="",F27=0),"",SUMIFS(Sales_Harian!$AF$8:$AF$507,Sales_Harian!$A$8:$A$507,$B$4,Sales_Harian!$B$8:$B$507,$A27)+SUMIFS(SPV_Harian!$AE$8:$AE$507,SPV_Harian!$A$8:$A$507,$B$4,SPV_Harian!$B$8:$B$507,$A27)+SUMIFS(ASM_Harian!$AE$8:$AE$507,ASM_Harian!$A$8:$A$507,$B$4,ASM_Harian!$B$8:$B$507,$A27)) | I27: =IF(OR($A27="",F27=0),"",SUMIFS(Sales_Harian!$AG$8:$AG$507,Sales_Harian!$A$8:$A$507,$B$4,Sales_Harian!$B$8:$B$507,$A27)+SUMIFS(SPV_Harian!$AF$8:$AF$507,SPV_Harian!$A$8:$A$507,$B$4,SPV_Harian!$B$8:$B$507,$A27)+SUMIFS(ASM_Harian!$AF$8:$AF$507,ASM_Harian!$A$8:$A$507,$B$4,ASM_Harian!$B$8:$B$507,$A27)) | J27: =IF(OR($A27="",F27=0),"",SUMIFS(Sales_Harian!$AH$8:$AH$507,Sales_Harian!$A$8:$A$507,$B$4,Sales_Harian!$B$8:$B$507,$A27)+SUMIFS(SPV_Harian!$AG$8:$AG$507,SPV_Harian!$A$8:$A$507,$B$4,SPV_Harian!$B$8:$B$507,$A27)+SUMIFS(ASM_Harian!$AG$8:$AG$507,ASM_Harian!$A$8:$A$507,$B$4,ASM_Harian!$B$8:$B$507,$A27)) | K27: =IF(OR($A27="",F27=0),"",SUMIFS(Sales_Harian!$AI$8:$AI$507,Sales_Harian!$A$8:$A$507,$B$4,Sales_Harian!$B$8:$B$507,$A27)+SUMIFS(SPV_Harian!$AH$8:$AH$507,SPV_Harian!$A$8:$A$507,$B$4,SPV_Harian!$B$8:$B$507,$A27)+SUMIFS(ASM_Harian!$AH$8:$AH$507,ASM_Harian!$A$8:$A$507,$B$4,ASM_Harian!$B$8:$B$507,$A27)) | L27: =IF(OR($A27="",F27=0),"",SUMIFS(Sales_Harian!$AK$8:$AK$507,Sales_Harian!$A$8:$A$507,$B$4,Sales_Harian!$B$8:$B$507,$A27)+SUMIFS(SPV_Harian!$AJ$8:$AJ$507,SPV_Harian!$A$8:$A$507,$B$4,SPV_Harian!$B$8:$B$507,$A27)+SUMIFS(ASM_Harian!$AJ$8:$AJ$507,ASM_Harian!$A$8:$A$507,$B$4,ASM_Harian!$B$8:$B$507,$A27)) | M27: =IF($A27="","",IF(OR(F27<>1,H27=0),"n.a.",I27/H27)) -> n.a. | N27: =IF($A27="","",IF(G27<>"Dikirim","",IF(COUNTIFS(Sales_Harian!$A$8:$A$507,$B$4,Sales_Harian!$B$8:$B$507,$A27,Sales_Harian!$AB$8:$AB$507,"Disetujui")+COUNTIFS(SPV_Harian!$A$8:$A$507,$B$4,SPV_Harian!$B$8:$B$507,$A27,SPV_Harian!$AA$8:$AA$507,"Disetujui")+COUNTIFS(ASM_Harian!$A$8:$A$507,$B$4,ASM_Harian!$B$8:$B$507,$A27,ASM_Harian!$AA$8:$AA$507,"Disetujui")=1,IF(COUNTIFS(Sales_Harian!$A$8:$A$507,$B$4,Sales_Harian!$B$8:$B$507,$A27,Sales_Harian!$AM$8:$AM$507,"<>OK")+COUNTIFS(SPV_Harian!$A$8:$A$507,$B$4,SPV_Harian!$B$8:$B$507,$A27,SPV_Harian!$AL$8:$AL$507,"<>OK")+COUNTIFS(ASM_Harian!$A$8:$A$507,$B$4,ASM_Harian!$B$8:$B$507,$A27,ASM_Harian!$AL$8:$AL$507,"<>OK")>0,"Review belum valid","Disetujui"),IF(COUNTIFS(Sales_Harian!$A$8:$A$507,$B$4,Sales_Harian!$B$8:$B$507,$A27,Sales_Harian!$AB$8:$AB$507,"Perlu Perbaikan")+COUNTIFS(SPV_Harian!$A$8:$A$507,$B$4,SPV_Harian!$B$8:$B$507,$A27,SPV_Harian!$AA$8:$AA$507,"Perlu Perbaikan")+COUNTIFS(ASM_Harian!$A$8:$A$507,$B$4,ASM_Harian!$B$8:$B$507,$A27,ASM_Harian!$AA$8:$AA$507,"Perlu Perbaikan")=1,"Perlu Perbaikan","Belum Diperiksa")))) | O27: =IF($A27="","",IF(F27=0,"Belum ada laporan",IF(F27>1,"Hapus/benahi laporan ganda",IF(COUNTIFS(Sales_Harian!$A$8:$A$507,$B$4,Sales_Harian!$B$8:$B$507,$A27,Sales_Harian!$AM$8:$AM$507,"<>OK")+COUNTIFS(SPV_Harian!$A$8:$A$507,$B$4,SPV_Harian!$B$8:$B$507,$A27,SPV_Harian!$AL$8:$AL$507,"<>OK")+COUNTIFS(ASM_Harian!$A$8:$A$507,$B$4,ASM_Harian!$B$8:$B$507,$A27,ASM_Harian!$AL$8:$AL$507,"<>OK")>0,"Periksa validasi_data",IF(SUM(J27:K27)>0,"Ada kegiatan terbuka",IF(N27="Perlu Perbaikan","Tindak lanjuti review",IF(G27="Draft","Kirim laporan",IF(N27="Belum Diperiksa","Menunggu pemeriksaan","")))))))) -> Belum ada laporan
A28: =IF(AND(Master_PIC!A17<>"",Master_PIC!G17="Aktif",Master_PIC!C17<>"Manager"),Master_PIC!A17,"") -> Sales06 | B28: =IF($A28="","",IF(Master_PIC!B17="","",Master_PIC!B17)) -> Sambudi SBFI | C28: =IF($A28="","",IF(Master_PIC!C17="","",Master_PIC!C17)) -> Sales | D28: =IF($A28="","",IF(Master_PIC!D17="","",Master_PIC!D17)) -> Cirebon 1 (Lokal) | E28: =IF($A28="","",IF(Master_PIC!E17="","",Master_PIC!E17)) -> Timur | F28: =IF($A28="","",COUNTIFS(Sales_Harian!$A$8:$A$507,$B$4,Sales_Harian!$B$8:$B$507,$A28)+COUNTIFS(SPV_Harian!$A$8:$A$507,$B$4,SPV_Harian!$B$8:$B$507,$A28)+COUNTIFS(ASM_Harian!$A$8:$A$507,$B$4,ASM_Harian!$B$8:$B$507,$A28)) -> 0 | G28: =IF($A28="","",IF(F28=0,"Belum Lapor",IF(F28>1,"Data Ganda",IF(COUNTIFS(Sales_Harian!$A$8:$A$507,$B$4,Sales_Harian!$B$8:$B$507,$A28,Sales_Harian!$Z$8:$Z$507,"Dikirim")+COUNTIFS(SPV_Harian!$A$8:$A$507,$B$4,SPV_Harian!$B$8:$B$507,$A28,SPV_Harian!$Y$8:$Y$507,"Dikirim")+COUNTIFS(ASM_Harian!$A$8:$A$507,$B$4,ASM_Harian!$B$8:$B$507,$A28,ASM_Harian!$Y$8:$Y$507,"Dikirim")=1,"Dikirim","Draft")))) -> Belum Lapor | H28: =IF(OR($A28="",F28=0),"",SUMIFS(Sales_Harian!$AF$8:$AF$507,Sales_Harian!$A$8:$A$507,$B$4,Sales_Harian!$B$8:$B$507,$A28)+SUMIFS(SPV_Harian!$AE$8:$AE$507,SPV_Harian!$A$8:$A$507,$B$4,SPV_Harian!$B$8:$B$507,$A28)+SUMIFS(ASM_Harian!$AE$8:$AE$507,ASM_Harian!$A$8:$A$507,$B$4,ASM_Harian!$B$8:$B$507,$A28)) | I28: =IF(OR($A28="",F28=0),"",SUMIFS(Sales_Harian!$AG$8:$AG$507,Sales_Harian!$A$8:$A$507,$B$4,Sales_Harian!$B$8:$B$507,$A28)+SUMIFS(SPV_Harian!$AF$8:$AF$507,SPV_Harian!$A$8:$A$507,$B$4,SPV_Harian!$B$8:$B$507,$A28)+SUMIFS(ASM_Harian!$AF$8:$AF$507,ASM_Harian!$A$8:$A$507,$B$4,ASM_Harian!$B$8:$B$507,$A28)) | J28: =IF(OR($A28="",F28=0),"",SUMIFS(Sales_Harian!$AH$8:$AH$507,Sales_Harian!$A$8:$A$507,$B$4,Sales_Harian!$B$8:$B$507,$A28)+SUMIFS(SPV_Harian!$AG$8:$AG$507,SPV_Harian!$A$8:$A$507,$B$4,SPV_Harian!$B$8:$B$507,$A28)+SUMIFS(ASM_Harian!$AG$8:$AG$507,ASM_Harian!$A$8:$A$507,$B$4,ASM_Harian!$B$8:$B$507,$A28)) | K28: =IF(OR($A28="",F28=0),"",SUMIFS(Sales_Harian!$AI$8:$AI$507,Sales_Harian!$A$8:$A$507,$B$4,Sales_Harian!$B$8:$B$507,$A28)+SUMIFS(SPV_Harian!$AH$8:$AH$507,SPV_Harian!$A$8:$A$507,$B$4,SPV_Harian!$B$8:$B$507,$A28)+SUMIFS(ASM_Harian!$AH$8:$AH$507,ASM_Harian!$A$8:$A$507,$B$4,ASM_Harian!$B$8:$B$507,$A28)) | L28: =IF(OR($A28="",F28=0),"",SUMIFS(Sales_Harian!$AK$8:$AK$507,Sales_Harian!$A$8:$A$507,$B$4,Sales_Harian!$B$8:$B$507,$A28)+SUMIFS(SPV_Harian!$AJ$8:$AJ$507,SPV_Harian!$A$8:$A$507,$B$4,SPV_Harian!$B$8:$B$507,$A28)+SUMIFS(ASM_Harian!$AJ$8:$AJ$507,ASM_Harian!$A$8:$A$507,$B$4,ASM_Harian!$B$8:$B$507,$A28)) | M28: =IF($A28="","",IF(OR(F28<>1,H28=0),"n.a.",I28/H28)) -> n.a. | N28: =IF($A28="","",IF(G28<>"Dikirim","",IF(COUNTIFS(Sales_Harian!$A$8:$A$507,$B$4,Sales_Harian!$B$8:$B$507,$A28,Sales_Harian!$AB$8:$AB$507,"Disetujui")+COUNTIFS(SPV_Harian!$A$8:$A$507,$B$4,SPV_Harian!$B$8:$B$507,$A28,SPV_Harian!$AA$8:$AA$507,"Disetujui")+COUNTIFS(ASM_Harian!$A$8:$A$507,$B$4,ASM_Harian!$B$8:$B$507,$A28,ASM_Harian!$AA$8:$AA$507,"Disetujui")=1,IF(COUNTIFS(Sales_Harian!$A$8:$A$507,$B$4,Sales_Harian!$B$8:$B$507,$A28,Sales_Harian!$AM$8:$AM$507,"<>OK")+COUNTIFS(SPV_Harian!$A$8:$A$507,$B$4,SPV_Harian!$B$8:$B$507,$A28,SPV_Harian!$AL$8:$AL$507,"<>OK")+COUNTIFS(ASM_Harian!$A$8:$A$507,$B$4,ASM_Harian!$B$8:$B$507,$A28,ASM_Harian!$AL$8:$AL$507,"<>OK")>0,"Review belum valid","Disetujui"),IF(COUNTIFS(Sales_Harian!$A$8:$A$507,$B$4,Sales_Harian!$B$8:$B$507,$A28,Sales_Harian!$AB$8:$AB$507,"Perlu Perbaikan")+COUNTIFS(SPV_Harian!$A$8:$A$507,$B$4,SPV_Harian!$B$8:$B$507,$A28,SPV_Harian!$AA$8:$AA$507,"Perlu Perbaikan")+COUNTIFS(ASM_Harian!$A$8:$A$507,$B$4,ASM_Harian!$B$8:$B$507,$A28,ASM_Harian!$AA$8:$AA$507,"Perlu Perbaikan")=1,"Perlu Perbaikan","Belum Diperiksa")))) | O28: =IF($A28="","",IF(F28=0,"Belum ada laporan",IF(F28>1,"Hapus/benahi laporan ganda",IF(COUNTIFS(Sales_Harian!$A$8:$A$507,$B$4,Sales_Harian!$B$8:$B$507,$A28,Sales_Harian!$AM$8:$AM$507,"<>OK")+COUNTIFS(SPV_Harian!$A$8:$A$507,$B$4,SPV_Harian!$B$8:$B$507,$A28,SPV_Harian!$AL$8:$AL$507,"<>OK")+COUNTIFS(ASM_Harian!$A$8:$A$507,$B$4,ASM_Harian!$B$8:$B$507,$A28,ASM_Harian!$AL$8:$AL$507,"<>OK")>0,"Periksa validasi_data",IF(SUM(J28:K28)>0,"Ada kegiatan terbuka",IF(N28="Perlu Perbaikan","Tindak lanjuti review",IF(G28="Draft","Kirim laporan",IF(N28="Belum Diperiksa","Menunggu pemeriksaan","")))))))) -> Belum ada laporan
A29: =IF(AND(Master_PIC!A18<>"",Master_PIC!G18="Aktif",Master_PIC!C18<>"Manager"),Master_PIC!A18,"") -> Sales07 | B29: =IF($A29="","",IF(Master_PIC!B18="","",Master_PIC!B18)) -> Hadi Supeno SBFI | C29: =IF($A29="","",IF(Master_PIC!C18="","",Master_PIC!C18)) -> Sales | D29: =IF($A29="","",IF(Master_PIC!D18="","",Master_PIC!D18)) -> Cirebon 1 (Lokal) | E29: =IF($A29="","",IF(Master_PIC!E18="","",Master_PIC!E18)) -> Timur | F29: =IF($A29="","",COUNTIFS(Sales_Harian!$A$8:$A$507,$B$4,Sales_Harian!$B$8:$B$507,$A29)+COUNTIFS(SPV_Harian!$A$8:$A$507,$B$4,SPV_Harian!$B$8:$B$507,$A29)+COUNTIFS(ASM_Harian!$A$8:$A$507,$B$4,ASM_Harian!$B$8:$B$507,$A29)) -> 0 | G29: =IF($A29="","",IF(F29=0,"Belum Lapor",IF(F29>1,"Data Ganda",IF(COUNTIFS(Sales_Harian!$A$8:$A$507,$B$4,Sales_Harian!$B$8:$B$507,$A29,Sales_Harian!$Z$8:$Z$507,"Dikirim")+COUNTIFS(SPV_Harian!$A$8:$A$507,$B$4,SPV_Harian!$B$8:$B$507,$A29,SPV_Harian!$Y$8:$Y$507,"Dikirim")+COUNTIFS(ASM_Harian!$A$8:$A$507,$B$4,ASM_Harian!$B$8:$B$507,$A29,ASM_Harian!$Y$8:$Y$507,"Dikirim")=1,"Dikirim","Draft")))) -> Belum Lapor | H29: =IF(OR($A29="",F29=0),"",SUMIFS(Sales_Harian!$AF$8:$AF$507,Sales_Harian!$A$8:$A$507,$B$4,Sales_Harian!$B$8:$B$507,$A29)+SUMIFS(SPV_Harian!$AE$8:$AE$507,SPV_Harian!$A$8:$A$507,$B$4,SPV_Harian!$B$8:$B$507,$A29)+SUMIFS(ASM_Harian!$AE$8:$AE$507,ASM_Harian!$A$8:$A$507,$B$4,ASM_Harian!$B$8:$B$507,$A29)) | I29: =IF(OR($A29="",F29=0),"",SUMIFS(Sales_Harian!$AG$8:$AG$507,Sales_Harian!$A$8:$A$507,$B$4,Sales_Harian!$B$8:$B$507,$A29)+SUMIFS(SPV_Harian!$AF$8:$AF$507,SPV_Harian!$A$8:$A$507,$B$4,SPV_Harian!$B$8:$B$507,$A29)+SUMIFS(ASM_Harian!$AF$8:$AF$507,ASM_Harian!$A$8:$A$507,$B$4,ASM_Harian!$B$8:$B$507,$A29)) | J29: =IF(OR($A29="",F29=0),"",SUMIFS(Sales_Harian!$AH$8:$AH$507,Sales_Harian!$A$8:$A$507,$B$4,Sales_Harian!$B$8:$B$507,$A29)+SUMIFS(SPV_Harian!$AG$8:$AG$507,SPV_Harian!$A$8:$A$507,$B$4,SPV_Harian!$B$8:$B$507,$A29)+SUMIFS(ASM_Harian!$AG$8:$AG$507,ASM_Harian!$A$8:$A$507,$B$4,ASM_Harian!$B$8:$B$507,$A29)) | K29: =IF(OR($A29="",F29=0),"",SUMIFS(Sales_Harian!$AI$8:$AI$507,Sales_Harian!$A$8:$A$507,$B$4,Sales_Harian!$B$8:$B$507,$A29)+SUMIFS(SPV_Harian!$AH$8:$AH$507,SPV_Harian!$A$8:$A$507,$B$4,SPV_Harian!$B$8:$B$507,$A29)+SUMIFS(ASM_Harian!$AH$8:$AH$507,ASM_Harian!$A$8:$A$507,$B$4,ASM_Harian!$B$8:$B$507,$A29)) | L29: =IF(OR($A29="",F29=0),"",SUMIFS(Sales_Harian!$AK$8:$AK$507,Sales_Harian!$A$8:$A$507,$B$4,Sales_Harian!$B$8:$B$507,$A29)+SUMIFS(SPV_Harian!$AJ$8:$AJ$507,SPV_Harian!$A$8:$A$507,$B$4,SPV_Harian!$B$8:$B$507,$A29)+SUMIFS(ASM_Harian!$AJ$8:$AJ$507,ASM_Harian!$A$8:$A$507,$B$4,ASM_Harian!$B$8:$B$507,$A29)) | M29: =IF($A29="","",IF(OR(F29<>1,H29=0),"n.a.",I29/H29)) -> n.a. | N29: =IF($A29="","",IF(G29<>"Dikirim","",IF(COUNTIFS(Sales_Harian!$A$8:$A$507,$B$4,Sales_Harian!$B$8:$B$507,$A29,Sales_Harian!$AB$8:$AB$507,"Disetujui")+COUNTIFS(SPV_Harian!$A$8:$A$507,$B$4,SPV_Harian!$B$8:$B$507,$A29,SPV_Harian!$AA$8:$AA$507,"Disetujui")+COUNTIFS(ASM_Harian!$A$8:$A$507,$B$4,ASM_Harian!$B$8:$B$507,$A29,ASM_Harian!$AA$8:$AA$507,"Disetujui")=1,IF(COUNTIFS(Sales_Harian!$A$8:$A$507,$B$4,Sales_Harian!$B$8:$B$507,$A29,Sales_Harian!$AM$8:$AM$507,"<>OK")+COUNTIFS(SPV_Harian!$A$8:$A$507,$B$4,SPV_Harian!$B$8:$B$507,$A29,SPV_Harian!$AL$8:$AL$507,"<>OK")+COUNTIFS(ASM_Harian!$A$8:$A$507,$B$4,ASM_Harian!$B$8:$B$507,$A29,ASM_Harian!$AL$8:$AL$507,"<>OK")>0,"Review belum valid","Disetujui"),IF(COUNTIFS(Sales_Harian!$A$8:$A$507,$B$4,Sales_Harian!$B$8:$B$507,$A29,Sales_Harian!$AB$8:$AB$507,"Perlu Perbaikan")+COUNTIFS(SPV_Harian!$A$8:$A$507,$B$4,SPV_Harian!$B$8:$B$507,$A29,SPV_Harian!$AA$8:$AA$507,"Perlu Perbaikan")+COUNTIFS(ASM_Harian!$A$8:$A$507,$B$4,ASM_Harian!$B$8:$B$507,$A29,ASM_Harian!$AA$8:$AA$507,"Perlu Perbaikan")=1,"Perlu Perbaikan","Belum Diperiksa")))) | O29: =IF($A29="","",IF(F29=0,"Belum ada laporan",IF(F29>1,"Hapus/benahi laporan ganda",IF(COUNTIFS(Sales_Harian!$A$8:$A$507,$B$4,Sales_Harian!$B$8:$B$507,$A29,Sales_Harian!$AM$8:$AM$507,"<>OK")+COUNTIFS(SPV_Harian!$A$8:$A$507,$B$4,SPV_Harian!$B$8:$B$507,$A29,SPV_Harian!$AL$8:$AL$507,"<>OK")+COUNTIFS(ASM_Harian!$A$8:$A$507,$B$4,ASM_Harian!$B$8:$B$507,$A29,ASM_Harian!$AL$8:$AL$507,"<>OK")>0,"Periksa validasi_data",IF(SUM(J29:K29)>0,"Ada kegiatan terbuka",IF(N29="Perlu Perbaikan","Tindak lanjuti review",IF(G29="Draft","Kirim laporan",IF(N29="Belum Diperiksa","Menunggu pemeriksaan","")))))))) -> Belum ada laporan
A30: =IF(AND(Master_PIC!A19<>"",Master_PIC!G19="Aktif",Master_PIC!C19<>"Manager"),Master_PIC!A19,"") -> Sales08 | B30: =IF($A30="","",IF(Master_PIC!B19="","",Master_PIC!B19)) -> Hadi Firmansyah | C30: =IF($A30="","",IF(Master_PIC!C19="","",Master_PIC!C19)) -> Sales | D30: =IF($A30="","",IF(Master_PIC!D19="","",Master_PIC!D19)) -> Cirebon 1 (Lokal) | E30: =IF($A30="","",IF(Master_PIC!E19="","",Master_PIC!E19)) -> Timur | F30: =IF($A30="","",COUNTIFS(Sales_Harian!$A$8:$A$507,$B$4,Sales_Harian!$B$8:$B$507,$A30)+COUNTIFS(SPV_Harian!$A$8:$A$507,$B$4,SPV_Harian!$B$8:$B$507,$A30)+COUNTIFS(ASM_Harian!$A$8:$A$507,$B$4,ASM_Harian!$B$8:$B$507,$A30)) -> 0 | G30: =IF($A30="","",IF(F30=0,"Belum Lapor",IF(F30>1,"Data Ganda",IF(COUNTIFS(Sales_Harian!$A$8:$A$507,$B$4,Sales_Harian!$B$8:$B$507,$A30,Sales_Harian!$Z$8:$Z$507,"Dikirim")+COUNTIFS(SPV_Harian!$A$8:$A$507,$B$4,SPV_Harian!$B$8:$B$507,$A30,SPV_Harian!$Y$8:$Y$507,"Dikirim")+COUNTIFS(ASM_Harian!$A$8:$A$507,$B$4,ASM_Harian!$B$8:$B$507,$A30,ASM_Harian!$Y$8:$Y$507,"Dikirim")=1,"Dikirim","Draft")))) -> Belum Lapor | H30: =IF(OR($A30="",F30=0),"",SUMIFS(Sales_Harian!$AF$8:$AF$507,Sales_Harian!$A$8:$A$507,$B$4,Sales_Harian!$B$8:$B$507,$A30)+SUMIFS(SPV_Harian!$AE$8:$AE$507,SPV_Harian!$A$8:$A$507,$B$4,SPV_Harian!$B$8:$B$507,$A30)+SUMIFS(ASM_Harian!$AE$8:$AE$507,ASM_Harian!$A$8:$A$507,$B$4,ASM_Harian!$B$8:$B$507,$A30)) | I30: =IF(OR($A30="",F30=0),"",SUMIFS(Sales_Harian!$AG$8:$AG$507,Sales_Harian!$A$8:$A$507,$B$4,Sales_Harian!$B$8:$B$507,$A30)+SUMIFS(SPV_Harian!$AF$8:$AF$507,SPV_Harian!$A$8:$A$507,$B$4,SPV_Harian!$B$8:$B$507,$A30)+SUMIFS(ASM_Harian!$AF$8:$AF$507,ASM_Harian!$A$8:$A$507,$B$4,ASM_Harian!$B$8:$B$507,$A30)) | J30: =IF(OR($A30="",F30=0),"",SUMIFS(Sales_Harian!$AH$8:$AH$507,Sales_Harian!$A$8:$A$507,$B$4,Sales_Harian!$B$8:$B$507,$A30)+SUMIFS(SPV_Harian!$AG$8:$AG$507,SPV_Harian!$A$8:$A$507,$B$4,SPV_Harian!$B$8:$B$507,$A30)+SUMIFS(ASM_Harian!$AG$8:$AG$507,ASM_Harian!$A$8:$A$507,$B$4,ASM_Harian!$B$8:$B$507,$A30)) | K30: =IF(OR($A30="",F30=0),"",SUMIFS(Sales_Harian!$AI$8:$AI$507,Sales_Harian!$A$8:$A$507,$B$4,Sales_Harian!$B$8:$B$507,$A30)+SUMIFS(SPV_Harian!$AH$8:$AH$507,SPV_Harian!$A$8:$A$507,$B$4,SPV_Harian!$B$8:$B$507,$A30)+SUMIFS(ASM_Harian!$AH$8:$AH$507,ASM_Harian!$A$8:$A$507,$B$4,ASM_Harian!$B$8:$B$507,$A30)) | L30: =IF(OR($A30="",F30=0),"",SUMIFS(Sales_Harian!$AK$8:$AK$507,Sales_Harian!$A$8:$A$507,$B$4,Sales_Harian!$B$8:$B$507,$A30)+SUMIFS(SPV_Harian!$AJ$8:$AJ$507,SPV_Harian!$A$8:$A$507,$B$4,SPV_Harian!$B$8:$B$507,$A30)+SUMIFS(ASM_Harian!$AJ$8:$AJ$507,ASM_Harian!$A$8:$A$507,$B$4,ASM_Harian!$B$8:$B$507,$A30)) | M30: =IF($A30="","",IF(OR(F30<>1,H30=0),"n.a.",I30/H30)) -> n.a. | N30: =IF($A30="","",IF(G30<>"Dikirim","",IF(COUNTIFS(Sales_Harian!$A$8:$A$507,$B$4,Sales_Harian!$B$8:$B$507,$A30,Sales_Harian!$AB$8:$AB$507,"Disetujui")+COUNTIFS(SPV_Harian!$A$8:$A$507,$B$4,SPV_Harian!$B$8:$B$507,$A30,SPV_Harian!$AA$8:$AA$507,"Disetujui")+COUNTIFS(ASM_Harian!$A$8:$A$507,$B$4,ASM_Harian!$B$8:$B$507,$A30,ASM_Harian!$AA$8:$AA$507,"Disetujui")=1,IF(COUNTIFS(Sales_Harian!$A$8:$A$507,$B$4,Sales_Harian!$B$8:$B$507,$A30,Sales_Harian!$AM$8:$AM$507,"<>OK")+COUNTIFS(SPV_Harian!$A$8:$A$507,$B$4,SPV_Harian!$B$8:$B$507,$A30,SPV_Harian!$AL$8:$AL$507,"<>OK")+COUNTIFS(ASM_Harian!$A$8:$A$507,$B$4,ASM_Harian!$B$8:$B$507,$A30,ASM_Harian!$AL$8:$AL$507,"<>OK")>0,"Review belum valid","Disetujui"),IF(COUNTIFS(Sales_Harian!$A$8:$A$507,$B$4,Sales_Harian!$B$8:$B$507,$A30,Sales_Harian!$AB$8:$AB$507,"Perlu Perbaikan")+COUNTIFS(SPV_Harian!$A$8:$A$507,$B$4,SPV_Harian!$B$8:$B$507,$A30,SPV_Harian!$AA$8:$AA$507,"Perlu Perbaikan")+COUNTIFS(ASM_Harian!$A$8:$A$507,$B$4,ASM_Harian!$B$8:$B$507,$A30,ASM_Harian!$AA$8:$AA$507,"Perlu Perbaikan")=1,"Perlu Perbaikan","Belum Diperiksa")))) | O30: =IF($A30="","",IF(F30=0,"Belum ada laporan",IF(F30>1,"Hapus/benahi laporan ganda",IF(COUNTIFS(Sales_Harian!$A$8:$A$507,$B$4,Sales_Harian!$B$8:$B$507,$A30,Sales_Harian!$AM$8:$AM$507,"<>OK")+COUNTIFS(SPV_Harian!$A$8:$A$507,$B$4,SPV_Harian!$B$8:$B$507,$A30,SPV_Harian!$AL$8:$AL$507,"<>OK")+COUNTIFS(ASM_Harian!$A$8:$A$507,$B$4,ASM_Harian!$B$8:$B$507,$A30,ASM_Harian!$AL$8:$AL$507,"<>OK")>0,"Periksa validasi_data",IF(SUM(J30:K30)>0,"Ada kegiatan terbuka",IF(N30="Perlu Perbaikan","Tindak lanjuti review",IF(G30="Draft","Kirim laporan",IF(N30="Belum Diperiksa","Menunggu pemeriksaan","")))))))) -> Belum ada laporan
A31: =IF(AND(Master_PIC!A20<>"",Master_PIC!G20="Aktif",Master_PIC!C20<>"Manager"),Master_PIC!A20,"") -> Sales09 | B31: =IF($A31="","",IF(Master_PIC!B20="","",Master_PIC!B20)) -> Sukeri | C31: =IF($A31="","",IF(Master_PIC!C20="","",Master_PIC!C20)) -> Sales | D31: =IF($A31="","",IF(Master_PIC!D20="","",Master_PIC!D20)) -> Cirebon 1 (Lokal) | E31: =IF($A31="","",IF(Master_PIC!E20="","",Master_PIC!E20)) -> Timur | F31: =IF($A31="","",COUNTIFS(Sales_Harian!$A$8:$A$507,$B$4,Sales_Harian!$B$8:$B$507,$A31)+COUNTIFS(SPV_Harian!$A$8:$A$507,$B$4,SPV_Harian!$B$8:$B$507,$A31)+COUNTIFS(ASM_Harian!$A$8:$A$507,$B$4,ASM_Harian!$B$8:$B$507,$A31)) -> 0 | G31: =IF($A31="","",IF(F31=0,"Belum Lapor",IF(F31>1,"Data Ganda",IF(COUNTIFS(Sales_Harian!$A$8:$A$507,$B$4,Sales_Harian!$B$8:$B$507,$A31,Sales_Harian!$Z$8:$Z$507,"Dikirim")+COUNTIFS(SPV_Harian!$A$8:$A$507,$B$4,SPV_Harian!$B$8:$B$507,$A31,SPV_Harian!$Y$8:$Y$507,"Dikirim")+COUNTIFS(ASM_Harian!$A$8:$A$507,$B$4,ASM_Harian!$B$8:$B$507,$A31,ASM_Harian!$Y$8:$Y$507,"Dikirim")=1,"Dikirim","Draft")))) -> Belum Lapor | H31: =IF(OR($A31="",F31=0),"",SUMIFS(Sales_Harian!$AF$8:$AF$507,Sales_Harian!$A$8:$A$507,$B$4,Sales_Harian!$B$8:$B$507,$A31)+SUMIFS(SPV_Harian!$AE$8:$AE$507,SPV_Harian!$A$8:$A$507,$B$4,SPV_Harian!$B$8:$B$507,$A31)+SUMIFS(ASM_Harian!$AE$8:$AE$507,ASM_Harian!$A$8:$A$507,$B$4,ASM_Harian!$B$8:$B$507,$A31)) | I31: =IF(OR($A31="",F31=0),"",SUMIFS(Sales_Harian!$AG$8:$AG$507,Sales_Harian!$A$8:$A$507,$B$4,Sales_Harian!$B$8:$B$507,$A31)+SUMIFS(SPV_Harian!$AF$8:$AF$507,SPV_Harian!$A$8:$A$507,$B$4,SPV_Harian!$B$8:$B$507,$A31)+SUMIFS(ASM_Harian!$AF$8:$AF$507,ASM_Harian!$A$8:$A$507,$B$4,ASM_Harian!$B$8:$B$507,$A31)) | J31: =IF(OR($A31="",F31=0),"",SUMIFS(Sales_Harian!$AH$8:$AH$507,Sales_Harian!$A$8:$A$507,$B$4,Sales_Harian!$B$8:$B$507,$A31)+SUMIFS(SPV_Harian!$AG$8:$AG$507,SPV_Harian!$A$8:$A$507,$B$4,SPV_Harian!$B$8:$B$507,$A31)+SUMIFS(ASM_Harian!$AG$8:$AG$507,ASM_Harian!$A$8:$A$507,$B$4,ASM_Harian!$B$8:$B$507,$A31)) | K31: =IF(OR($A31="",F31=0),"",SUMIFS(Sales_Harian!$AI$8:$AI$507,Sales_Harian!$A$8:$A$507,$B$4,Sales_Harian!$B$8:$B$507,$A31)+SUMIFS(SPV_Harian!$AH$8:$AH$507,SPV_Harian!$A$8:$A$507,$B$4,SPV_Harian!$B$8:$B$507,$A31)+SUMIFS(ASM_Harian!$AH$8:$AH$507,ASM_Harian!$A$8:$A$507,$B$4,ASM_Harian!$B$8:$B$507,$A31)) | L31: =IF(OR($A31="",F31=0),"",SUMIFS(Sales_Harian!$AK$8:$AK$507,Sales_Harian!$A$8:$A$507,$B$4,Sales_Harian!$B$8:$B$507,$A31)+SUMIFS(SPV_Harian!$AJ$8:$AJ$507,SPV_Harian!$A$8:$A$507,$B$4,SPV_Harian!$B$8:$B$507,$A31)+SUMIFS(ASM_Harian!$AJ$8:$AJ$507,ASM_Harian!$A$8:$A$507,$B$4,ASM_Harian!$B$8:$B$507,$A31)) | M31: =IF($A31="","",IF(OR(F31<>1,H31=0),"n.a.",I31/H31)) -> n.a. | N31: =IF($A31="","",IF(G31<>"Dikirim","",IF(COUNTIFS(Sales_Harian!$A$8:$A$507,$B$4,Sales_Harian!$B$8:$B$507,$A31,Sales_Harian!$AB$8:$AB$507,"Disetujui")+COUNTIFS(SPV_Harian!$A$8:$A$507,$B$4,SPV_Harian!$B$8:$B$507,$A31,SPV_Harian!$AA$8:$AA$507,"Disetujui")+COUNTIFS(ASM_Harian!$A$8:$A$507,$B$4,ASM_Harian!$B$8:$B$507,$A31,ASM_Harian!$AA$8:$AA$507,"Disetujui")=1,IF(COUNTIFS(Sales_Harian!$A$8:$A$507,$B$4,Sales_Harian!$B$8:$B$507,$A31,Sales_Harian!$AM$8:$AM$507,"<>OK")+COUNTIFS(SPV_Harian!$A$8:$A$507,$B$4,SPV_Harian!$B$8:$B$507,$A31,SPV_Harian!$AL$8:$AL$507,"<>OK")+COUNTIFS(ASM_Harian!$A$8:$A$507,$B$4,ASM_Harian!$B$8:$B$507,$A31,ASM_Harian!$AL$8:$AL$507,"<>OK")>0,"Review belum valid","Disetujui"),IF(COUNTIFS(Sales_Harian!$A$8:$A$507,$B$4,Sales_Harian!$B$8:$B$507,$A31,Sales_Harian!$AB$8:$AB$507,"Perlu Perbaikan")+COUNTIFS(SPV_Harian!$A$8:$A$507,$B$4,SPV_Harian!$B$8:$B$507,$A31,SPV_Harian!$AA$8:$AA$507,"Perlu Perbaikan")+COUNTIFS(ASM_Harian!$A$8:$A$507,$B$4,ASM_Harian!$B$8:$B$507,$A31,ASM_Harian!$AA$8:$AA$507,"Perlu Perbaikan")=1,"Perlu Perbaikan","Belum Diperiksa")))) | O31: =IF($A31="","",IF(F31=0,"Belum ada laporan",IF(F31>1,"Hapus/benahi laporan ganda",IF(COUNTIFS(Sales_Harian!$A$8:$A$507,$B$4,Sales_Harian!$B$8:$B$507,$A31,Sales_Harian!$AM$8:$AM$507,"<>OK")+COUNTIFS(SPV_Harian!$A$8:$A$507,$B$4,SPV_Harian!$B$8:$B$507,$A31,SPV_Harian!$AL$8:$AL$507,"<>OK")+COUNTIFS(ASM_Harian!$A$8:$A$507,$B$4,ASM_Harian!$B$8:$B$507,$A31,ASM_Harian!$AL$8:$AL$507,"<>OK")>0,"Periksa validasi_data",IF(SUM(J31:K31)>0,"Ada kegiatan terbuka",IF(N31="Perlu Perbaikan","Tindak lanjuti review",IF(G31="Draft","Kirim laporan",IF(N31="Belum Diperiksa","Menunggu pemeriksaan","")))))))) -> Belum ada laporan
A32: =IF(AND(Master_PIC!A21<>"",Master_PIC!G21="Aktif",Master_PIC!C21<>"Manager"),Master_PIC!A21,"") -> Sales10 | B32: =IF($A32="","",IF(Master_PIC!B21="","",Master_PIC!B21)) -> Mohammad Suyatno | C32: =IF($A32="","",IF(Master_PIC!C21="","",Master_PIC!C21)) -> Sales | D32: =IF($A32="","",IF(Master_PIC!D21="","",Master_PIC!D21)) -> Cirebon 1 (Lokal) | E32: =IF($A32="","",IF(Master_PIC!E21="","",Master_PIC!E21)) -> Timur | F32: =IF($A32="","",COUNTIFS(Sales_Harian!$A$8:$A$507,$B$4,Sales_Harian!$B$8:$B$507,$A32)+COUNTIFS(SPV_Harian!$A$8:$A$507,$B$4,SPV_Harian!$B$8:$B$507,$A32)+COUNTIFS(ASM_Harian!$A$8:$A$507,$B$4,ASM_Harian!$B$8:$B$507,$A32)) -> 0 | G32: =IF($A32="","",IF(F32=0,"Belum Lapor",IF(F32>1,"Data Ganda",IF(COUNTIFS(Sales_Harian!$A$8:$A$507,$B$4,Sales_Harian!$B$8:$B$507,$A32,Sales_Harian!$Z$8:$Z$507,"Dikirim")+COUNTIFS(SPV_Harian!$A$8:$A$507,$B$4,SPV_Harian!$B$8:$B$507,$A32,SPV_Harian!$Y$8:$Y$507,"Dikirim")+COUNTIFS(ASM_Harian!$A$8:$A$507,$B$4,ASM_Harian!$B$8:$B$507,$A32,ASM_Harian!$Y$8:$Y$507,"Dikirim")=1,"Dikirim","Draft")))) -> Belum Lapor | H32: =IF(OR($A32="",F32=0),"",SUMIFS(Sales_Harian!$AF$8:$AF$507,Sales_Harian!$A$8:$A$507,$B$4,Sales_Harian!$B$8:$B$507,$A32)+SUMIFS(SPV_Harian!$AE$8:$AE$507,SPV_Harian!$A$8:$A$507,$B$4,SPV_Harian!$B$8:$B$507,$A32)+SUMIFS(ASM_Harian!$AE$8:$AE$507,ASM_Harian!$A$8:$A$507,$B$4,ASM_Harian!$B$8:$B$507,$A32)) | I32: =IF(OR($A32="",F32=0),"",SUMIFS(Sales_Harian!$AG$8:$AG$507,Sales_Harian!$A$8:$A$507,$B$4,Sales_Harian!$B$8:$B$507,$A32)+SUMIFS(SPV_Harian!$AF$8:$AF$507,SPV_Harian!$A$8:$A$507,$B$4,SPV_Harian!$B$8:$B$507,$A32)+SUMIFS(ASM_Harian!$AF$8:$AF$507,ASM_Harian!$A$8:$A$507,$B$4,ASM_Harian!$B$8:$B$507,$A32)) | J32: =IF(OR($A32="",F32=0),"",SUMIFS(Sales_Harian!$AH$8:$AH$507,Sales_Harian!$A$8:$A$507,$B$4,Sales_Harian!$B$8:$B$507,$A32)+SUMIFS(SPV_Harian!$AG$8:$AG$507,SPV_Harian!$A$8:$A$507,$B$4,SPV_Harian!$B$8:$B$507,$A32)+SUMIFS(ASM_Harian!$AG$8:$AG$507,ASM_Harian!$A$8:$A$507,$B$4,ASM_Harian!$B$8:$B$507,$A32)) | K32: =IF(OR($A32="",F32=0),"",SUMIFS(Sales_Harian!$AI$8:$AI$507,Sales_Harian!$A$8:$A$507,$B$4,Sales_Harian!$B$8:$B$507,$A32)+SUMIFS(SPV_Harian!$AH$8:$AH$507,SPV_Harian!$A$8:$A$507,$B$4,SPV_Harian!$B$8:$B$507,$A32)+SUMIFS(ASM_Harian!$AH$8:$AH$507,ASM_Harian!$A$8:$A$507,$B$4,ASM_Harian!$B$8:$B$507,$A32)) | L32: =IF(OR($A32="",F32=0),"",SUMIFS(Sales_Harian!$AK$8:$AK$507,Sales_Harian!$A$8:$A$507,$B$4,Sales_Harian!$B$8:$B$507,$A32)+SUMIFS(SPV_Harian!$AJ$8:$AJ$507,SPV_Harian!$A$8:$A$507,$B$4,SPV_Harian!$B$8:$B$507,$A32)+SUMIFS(ASM_Harian!$AJ$8:$AJ$507,ASM_Harian!$A$8:$A$507,$B$4,ASM_Harian!$B$8:$B$507,$A32)) | M32: =IF($A32="","",IF(OR(F32<>1,H32=0),"n.a.",I32/H32)) -> n.a. | N32: =IF($A32="","",IF(G32<>"Dikirim","",IF(COUNTIFS(Sales_Harian!$A$8:$A$507,$B$4,Sales_Harian!$B$8:$B$507,$A32,Sales_Harian!$AB$8:$AB$507,"Disetujui")+COUNTIFS(SPV_Harian!$A$8:$A$507,$B$4,SPV_Harian!$B$8:$B$507,$A32,SPV_Harian!$AA$8:$AA$507,"Disetujui")+COUNTIFS(ASM_Harian!$A$8:$A$507,$B$4,ASM_Harian!$B$8:$B$507,$A32,ASM_Harian!$AA$8:$AA$507,"Disetujui")=1,IF(COUNTIFS(Sales_Harian!$A$8:$A$507,$B$4,Sales_Harian!$B$8:$B$507,$A32,Sales_Harian!$AM$8:$AM$507,"<>OK")+COUNTIFS(SPV_Harian!$A$8:$A$507,$B$4,SPV_Harian!$B$8:$B$507,$A32,SPV_Harian!$AL$8:$AL$507,"<>OK")+COUNTIFS(ASM_Harian!$A$8:$A$507,$B$4,ASM_Harian!$B$8:$B$507,$A32,ASM_Harian!$AL$8:$AL$507,"<>OK")>0,"Review belum valid","Disetujui"),IF(COUNTIFS(Sales_Harian!$A$8:$A$507,$B$4,Sales_Harian!$B$8:$B$507,$A32,Sales_Harian!$AB$8:$AB$507,"Perlu Perbaikan")+COUNTIFS(SPV_Harian!$A$8:$A$507,$B$4,SPV_Harian!$B$8:$B$507,$A32,SPV_Harian!$AA$8:$AA$507,"Perlu Perbaikan")+COUNTIFS(ASM_Harian!$A$8:$A$507,$B$4,ASM_Harian!$B$8:$B$507,$A32,ASM_Harian!$AA$8:$AA$507,"Perlu Perbaikan")=1,"Perlu Perbaikan","Belum Diperiksa")))) | O32: =IF($A32="","",IF(F32=0,"Belum ada laporan",IF(F32>1,"Hapus/benahi laporan ganda",IF(COUNTIFS(Sales_Harian!$A$8:$A$507,$B$4,Sales_Harian!$B$8:$B$507,$A32,Sales_Harian!$AM$8:$AM$507,"<>OK")+COUNTIFS(SPV_Harian!$A$8:$A$507,$B$4,SPV_Harian!$B$8:$B$507,$A32,SPV_Harian!$AL$8:$AL$507,"<>OK")+COUNTIFS(ASM_Harian!$A$8:$A$507,$B$4,ASM_Harian!$B$8:$B$507,$A32,ASM_Harian!$AL$8:$AL$507,"<>OK")>0,"Periksa validasi_data",IF(SUM(J32:K32)>0,"Ada kegiatan terbuka",IF(N32="Perlu Perbaikan","Tindak lanjuti review",IF(G32="Draft","Kirim laporan",IF(N32="Belum Diperiksa","Menunggu pemeriksaan","")))))))) -> Belum ada laporan
